Workbook
Name A_ALL_000050.SZ: #REF!
Name A_ALL_000413.SZ: #REF!
Name A_ALL_000725.SZ: #REF!
Name A_ALL_002371.SZ: #REF!
Name A_ALL_002415.SZ: #REF!
Name A_ALL_002415.SZ_: #REF!
Name A_ALL_002456.SZ: #REF!
Name A_ALL_002876.SZ: #REF!
Name A_ALL_2018.HK: #REF!
Name A_ALL_2303.TW: #REF!
Name A_ALL_4966.TWO: #REF!
Name A_ALL_600584.SS: #REF!
Name A_ALL_600699.SS: #REF!
Name A_ALL_603986.SS: #REF!
Name A_ALL_6415.TW: #REF!
Name A_ALL_KEYWORDS_TYPE_Breakdown_EQTY_200008919: #REF!
Name A_ALL_KEYWORDS_TYPE_ScalarContributed_EQTY_200006786: #REF!,#REF!,#REF!,#REF!
Name A_ALL_KEYWORDS_TYPE_ScalarContributed_EQTY_200008919: #REF!,#REF!
Name A_ALL_KEYWORDS_TYPE_ScalarContributed_EQTY_200011172: #REF!,#REF!
Name A_ALL_KEYWORDS_TYPE_ScalarContributed_EQTY_200012735: #REF!,#REF!
Name A_ALL_KEYWORDS_TYPE_ScalarContributed_EQTY_200012909: #REF!,#REF!
Name A_ALL_KEYWORDS_TYPE_ScalarContributed_EQTY_200012913: #REF!,#REF!
Name A_ALL_KEYWORDS_TYPE_ScalarContributed_EQTY_200016087: #REF!,#REF!
Name A_ALL_KEYWORDS_TYPE_ScalarContributed_EQTY_200019558: #REF!,#REF!
Name A_ALL_KEYWORDS_TYPE_ScalarContributed_EQTY_200019559: #REF!,#REF!
Name A_ALL_KEYWORDS_TYPE_ScalarContributed_EQTY_200019876: #REF!,#REF!,#REF!
Name A_ALL_KEYWORDS_TYPE_ScalarContributed_ISSR_208002015: #REF!,#REF!
Name A_ALL_KEYWORDS_TYPE_ScalarContributed_ISSR_208007067: #REF!,#REF!
Name A_ALL_KEYWORDS_TYPE_ScalarContributed_ISSR_208010212: #REF!,#REF!
Name A_ALL_KEYWORDS_TYPE_ScalarContributed_ISSR_208015000: #REF!,#REF!
Name A_ALL_KEYWORDS_TYPE_ScalarContributed_ISSR_208019081: #REF!,#REF!
Name A_ALL_KEYWORDS_TYPE_ScalarContributed_ISSR_208019322: #REF!,#REF!
Name A_ALL_KEYWORDS_TYPE_ScalarContributed_ISSR_208021173: #REF!,#REF!
Name A_ALL_KEYWORDS_TYPE_ScalarContributed_ISSR_208021175: #REF!,#REF!
Name A_ALL_KEYWORDS_TYPE_Vector_EQTY_200006785: #REF!,#REF!,#REF!,#REF!,#REF!
Name A_ALL_KEYWORDS_TYPE_Vector_EQTY_200006786: #REF!,#REF!,#REF!,#REF!,#REF!,#REF!
Name A_ALL_KEYWORDS_TYPE_Vector_EQTY_200008918: #REF!,#REF!,#REF!,#REF!,#REF!
Name A_ALL_KEYWORDS_TYPE_Vector_EQTY_200011172: #REF!,#REF!,#REF!,#REF!,#REF!
Name A_ALL_KEYWORDS_TYPE_Vector_EQTY_200012735: #REF!,#REF!,#REF!,#REF!,#REF!
Name A_ALL_KEYWORDS_TYPE_Vector_EQTY_200012909: #REF!,#REF!,#REF!,#REF!,#REF!
Name A_ALL_KEYWORDS_TYPE_Vector_EQTY_200012913: #REF!,#REF!,#REF!,#REF!,#REF!
Name A_ALL_KEYWORDS_TYPE_Vector_EQTY_200013283: #REF!,#REF!,#REF!,#REF!,#REF!
Name A_ALL_KEYWORDS_TYPE_Vector_EQTY_200016087: #REF!,#REF!,#REF!,#REF!,#REF!
Name A_ALL_KEYWORDS_TYPE_Vector_EQTY_200017468: #REF!,#REF!,#REF!,#REF!,#REF!
Name A_ALL_KEYWORDS_TYPE_Vector_EQTY_200018245: #REF!,#REF!,#REF!,#REF!,#REF!
Name A_ALL_KEYWORDS_TYPE_Vector_EQTY_200020142: #REF!,#REF!,#REF!,#REF!,#REF!
Name A_ALL_KEYWORDS_TYPE_Vector_EQTY_200020296: #REF!,#REF!,#REF!,#REF!,#REF!
Name A_ALL_KEYWORDS_TYPE_Vector_EQTY_200021697: #REF!,#REF!,#REF!,#REF!,#REF!
Name A_ALL_KEYWORDS_TYPE_Vector_EQTY_200021698: #REF!,#REF!,#REF!,#REF!,#REF!
Name A_ALL_KEYWORDS_TYPE_Vector_ISSR_208002015: #REF!,#REF!,#REF!,#REF!,#REF!,#REF!,#REF!,#REF!,#REF!,#REF!,#REF!,#REF!,#REF!
Name A_ALL_KEYWORDS_TYPE_Vector_ISSR_208006410: #REF!,#REF!,#REF!,#REF!,#REF!,#REF!,#REF!,#REF!,#REF!,#REF!,#REF!
Name A_ALL_KEYWORDS_TYPE_Vector_ISSR_208007067: #REF!,#REF!,#REF!,#REF!,#REF!,#REF!,#REF!,#REF!,#REF!,#REF!,#REF!,#REF!,#REF!
Name A_ALL_KEYWORDS_TYPE_Vector_ISSR_208008548: #REF!,#REF!,#REF!,#REF!,#REF!,#REF!,#REF!,#REF!,#REF!,#REF!,#REF!,#REF!,#REF!,#REF!,#REF!,#REF!
Name A_ALL_KEYWORDS_TYPE_Vector_ISSR_208009698: #REF!,#REF!,#REF!,#REF!,#REF!,#REF!,#REF!,#REF!,#REF!,#REF!,#REF!,#REF!,#REF!,#REF!
Name A_ALL_KEYWORDS_TYPE_Vector_ISSR_208009912: #REF!,#REF!,#REF!,#REF!,#REF!,#REF!,#REF!,#REF!,#REF!,#REF!,#REF!,#REF!,#REF!,#REF!,#REF!
Name A_ALL_KEYWORDS_TYPE_Vector_ISSR_208009916: #REF!,#REF!,#REF!,#REF!,#REF!,#REF!,#REF!,#REF!,#REF!,#REF!,#REF!,#REF!,#REF!,#REF!
Name A_ALL_KEYWORDS_TYPE_Vector_ISSR_208010212: #REF!,#REF!,#REF!,#REF!,#REF!,#REF!,#REF!,#REF!,#REF!,#REF!,#REF!,#REF!,#REF!,#REF!
Name A_ALL_KEYWORDS_TYPE_Vector_ISSR_208011603: #REF!,#REF!,#REF!,#REF!,#REF!,#REF!,#REF!,#REF!,#REF!,#REF!,#REF!
Name A_ALL_KEYWORDS_TYPE_Vector_ISSR_208013035: #REF!,#REF!,#REF!,#REF!,#REF!,#REF!,#REF!,#REF!,#REF!,#REF!,#REF!,#REF!,#REF!,#REF!,#REF!
Name A_ALL_KEYWORDS_TYPE_Vector_ISSR_208013036: #REF!,#REF!,#REF!,#REF!,#REF!,#REF!,#REF!,#REF!,#REF!,#REF!,#REF!

Sheet Model
A2: Innolight (300308.SZ)
A3: In Rmb millions | W3: 2014 | X3: 2014 | Y3: 2014 | Z3: 2014 | AA3: =W3+1 -> 2015 | AB3: =X3+1 -> 2015 | AC3: =Y3+1 -> 2015 | AD3: =Z3+1 -> 2015 | AE3: =AA3+1 -> 2016 | AF3: =AB3+1 -> 2016 | AG3: =AC3+1 -> 2016 | AH3: =AD3+1 -> 2016 | ... BZ3: =BV3+1 -> 2027
C4: 2009 | D4: 2010 | E4: 2011 | F4: 2012 | G4: 2013 | H4: 2014 | I4: 2015 | J4: 2016 | K4: 2017 | L4: =K4+1 -> 2018 | M4: =L4+1 -> 2019 | N4: =M4+1 -> 2020 | O4: =N4+1 -> 2021 | P4: =O4+1 -> 2022 | Q4: =P4+1 -> 2023 | R4: =Q4+1 -> 2024 | S4: =R4+1 -> 2025 | ... U4: =T4+1 -> 2027 | W4: 1Q14 | X4: 2Q14 | Y4: 3Q14 | Z4: 4Q14 | AA4: 1Q15 | AB4: 2Q15 | AC4: 3Q15 | AD4: 4Q15 | AE4: 1Q16 | AF4: 2Q16 | AG4: 3Q16 | AH4: 4Q16 | AI4: 1Q17 | AJ4: 2Q17 | AK4: 3Q17 | AL4: 4Q17 | AM4: 1Q18 | AN4: 2Q18 | AO4: 3Q18 | AP4: 4Q18 | AQ4: 1Q19 | AR4: 2Q19 | AS4: 3Q19 | AT4: 4Q19 | AU4: 1Q20 | AV4: 2Q20 | AW4: 3Q20 | AX4: 4Q20 | AY4: 1Q21 | AZ4: 2Q21 | BA4: 3Q21 | BB4: 4Q21 | BC4: 1Q22 | BD4: 2Q22 | BE4: 3Q22 | BF4: 4Q22 | BG4: 1Q23 | BH4: 2Q23 | BI4: 3Q23 | BJ4: 4Q23 | BK4: 1Q24 | BL4: 2Q24 | BM4: 3Q24 | BN4: 4Q24 | BO4: 1Q25 | BP4: 2Q25 | BQ4: 3Q25 | BR4: 4Q25 | BS4: 1Q26 | BT4: 2Q26 | BU4: 3Q26 | BV4: 4Q26 | BW4: 1Q27 | BX4: 2Q27 | BY4: 3Q27 | BZ4: 4Q27
B5: Income statements | C5: =C4 -> 2009 | D5: =D4 -> 2010 | E5: =E4 -> 2011 | F5: =F4 -> 2012 | G5: =G4 -> 2013 | H5: =H4 -> 2014 | I5: =I4 -> 2015 | J5: =J4 -> 2016 | ... U5: =U4 -> 2027 | W5: =W4 -> 1Q14 | X5: =X4 -> 2Q14 | Y5: =Y4 -> 3Q14 | Z5: =Z4 -> 4Q14 | AA5: =AA4 -> 1Q15 | AB5: =AB4 -> 2Q15 | AC5: =AC4 -> 3Q15 | AD5: =AD4 -> 4Q15 | ... BZ5: =BZ4 -> 4Q27
B7: Total sales/revenues | C7: 90.373718 | D7: 123.54713 | E7: 162.07917 | F7: 116.65963 | G7: 90.52615 | H7: 118.74621 | I7: 121.40994 | J7: 131.62038 | K7: 2357.0835 | L7: 5156.3142 | M7: 4757.677 | N7: 7049.5901 | O7: 7695.4048 | P7: =SUMIF($W$3:$BR$3,P$4,$W7:$BR7) -> 9641.7948 | Q7: =SUMIF($W$3:$BR$3,Q$4,$W7:$BR7) -> 10717.984 | R7: =SUMIF($W$3:$BR$3,R$4,$W7:$BR7) -> 23862.16 | S7: =SUMIF($W$3:$BR$3,S$4,$W7:$BR7) -> 35041.957 | T7: =SUMIF($W$3:$BZ$3,T$4,$W7:$BZ7) -> 50582.612 | U7: =SUMIF($W$3:$BZ$3,U$4,$W7:$BZ7) -> 61409.384 | W7: 38.360696 | X7: 19.824628 | Y7: 21.886566 | Z7: 38.674316 | AA7: 19.18802 | AB7: 23.88869 | AC7: 26.209578 | AD7: 52.123649 | AE7: 10.325244 | AF7: 46.362725 | AG7: 25.951711 | AH7: 48.980704 | AI7: 14.564576 | AJ7: 56.023104 | AK7: 1068.8855 | AL7: 1217.6103 | AM7: 1398.5982 | AN7: 1426.9623 | AO7: 1377.2606 | AP7: 953.49315 | AQ7: 875.64684 | AR7: 1159.5558 | AS7: 1248.7111 | AT7: 1473.7632 | AU7: 1326.0904 | AV7: 1918.5856 | AW7: 1960.1096 | AX7: 1844.8045 | AY7: 1471.7584 | AZ7: 1826.094 | BA7: 2024.2344 | BB7: 2373.318 | BC7: 2088.6226 | BD7: 2142.4212 | BE7: 2633.9444 | BF7: 2776.8065 | BG7: 1837.1632 | BH7: 2166.818 | BI7: 3026.3091 | BJ7: 3687.6941 | BK7: 4842.5469 | BL7: 5956.0473 | BM7: 6514.0076 | BN7: 6549.5579 | BO7: 6674.1765 | BP7: 8114.8984 | BQ7: =Assumption!P12 -> 9544.9328 | BR7: =Assumption!Q12 -> 10707.949 | BS7: =Assumption!R12 -> 10818.019 | BT7: =Assumption!S12 -> 12058.533 | BU7: =Assumption!T12 -> 13278.777 | BV7: =Assumption!U12 -> 14427.284 | BW7: =Assumption!V12 -> 13381.138 | BX7: =Assumption!W12 -> 15125.613 | ... BZ7: =Assumption!Y12 -> 16752.354
B8: COGS | C8: 45.395267 | D8: 60.78985 | E8: 80.740715 | F8: 59.862063 | G8: 53.85313 | H8: 80.199978 | I8: 88.449923 | J8: 91.398229 | K8: 1725.5088 | L8: 3749.9692 | M8: 3467.7751 | N8: 5256.9582 | O8: 5727.3999 | P8: =SUMIF($W$3:$BR$3,P$4,$W8:$BR8) -> 6815.5917 | Q8: =SUMIF($W$3:$BR$3,Q$4,$W8:$BR8) -> 7181.8774 | R8: =SUMIF($W$3:$BR$3,R$4,$W8:$BR8) -> 15795.567 | S8: =SUMIF($W$3:$BR$3,S$4,$W8:$BR8) -> 20461.892 | T8: =SUMIF($W$3:$BZ$3,T$4,$W8:$BZ8) -> 27736.865 | U8: =SUMIF($W$3:$BZ$3,U$4,$W8:$BZ8) -> 33440.372 | W8: 25.231973 | X8: 13.893568 | Y8: 15.721471 | Z8: 25.352966 | AA8: 16.14646 | AB8: 14.791145 | AC8: 19.536104 | AD8: 37.976214 | AE8: 6.930456 | AF8: 33.933494 | AG8: 18.631501 | AH8: 31.902778 | AI8: 9.9617218 | AJ8: 36.66104 | AK8: 781.51313 | AL8: 897.37294 | AM8: 1058.9192 | AN8: 1056.9059 | AO8: 992.99302 | AP8: 641.151 | AQ8: 629.53872 | AR8: 826.71743 | AS8: 898.30543 | AT8: 1113.2135 | AU8: 995.31096 | AV8: 1428.5533 | AW8: 1482.6544 | AX8: 1350.4395 | AY8: 1102.2124 | AZ8: 1390.9275 | BA8: 1527.9706 | BB8: 1706.2893 | BC8: 1539.71 | BD8: 1558.047 | BE8: 1850.7677 | BF8: 1867.067 | BG8: 1294.2925 | BH8: 1492.9706 | BI8: 2011.1547 | BJ8: 2383.4596 | BK8: 3256.1729 | BL8: 3964.601 | BM8: 4323.0185 | BN8: 4251.7742 | BO8: 4224.6871 | BP8: 4748.2798 | BQ8: =(BQ7-BQ12) -> 5453.9066 | BR8: =(BR7-BR12) -> 6035.0181 | BS8: =(BS7-BS12) -> 6021.4456 | BT8: =(BT7-BT12) -> 6689.9262 | BU8: =(BU7-BU12) -> 7235.995 | BV8: =(BV7-BV12) -> 7789.4979 | BW8: =(BW7-BW12) -> 7398.0969 | BX8: =(BX7-BX12) -> 8331.0321 | ... BZ8: =(BZ7-BZ12) -> 8945.2654
B9: Others | BA9: 0 | BB9: 0 | BC9: 0 | BD9: 0 | BE9: 0 | BF9: 0 | BG9: 0 | BH9: 0 | BI9: 0 | BJ9: 0 | BK9: 0 | BL9: 0 | BM9: 0 | BN9: 0 | BO9: 0 | BP9: 0 | BQ9: 0 | BR9: 0 | BS9: 0 | BT9: 0 | BU9: 0 | BV9: 0 | BW9: 0 | BX9: 0 | BY9: 0 | BZ9: 0
B10: Total COGS | C10: =C8+C9 -> 45.395267 | D10: =D8+D9 -> 60.78985 | E10: =E8+E9 -> 80.740715 | F10: =F8+F9 -> 59.862063 | G10: =G8+G9 -> 53.85313 | H10: =H8+H9 -> 80.199978 | I10: =I8+I9 -> 88.449923 | J10: =J8+J9 -> 91.398229 | ... U10: =U8+U9 -> 33440.372 | W10: =W8+W9 -> 25.231973 | X10: =X8+X9 -> 13.893568 | Y10: =Y8+Y9 -> 15.721471 | Z10: =Z8+Z9 -> 25.352966 | AA10: =AA8+AA9 -> 16.14646 | AB10: =AB8+AB9 -> 14.791145 | AC10: =AC8+AC9 -> 19.536104 | AD10: =AD8+AD9 -> 37.976214 | ... BZ10: =BZ8+BZ9 -> 8945.2654
B12: Gross profit | C12: =+C7-C10 -> 44.978451 | D12: =+D7-D10 -> 62.757275 | E12: =+E7-E10 -> 81.338459 | F12: =+F7-F10 -> 56.797565 | G12: =+G7-G10 -> 36.673021 | H12: =+H7-H10 -> 38.546229 | I12: =+I7-I10 -> 32.960014 | J12: =+J7-J10 -> 40.222155 | ... U12: =+U7-U10 -> 27969.012 | W12: =+W7-W8 -> 13.128723 | X12: =+X7-X8 -> 5.9310606 | Y12: =+Y7-Y8 -> 6.1650949 | Z12: =+Z7-Z8 -> 13.321351 | AA12: =+AA7-AA8 -> 3.04156 | AB12: =+AB7-AB8 -> 9.0975455 | AC12: =+AC7-AC8 -> 6.6734737 | AD12: =+AD7-AD8 -> 14.147435 | ... BP12: =+BP7-BP8 -> 3366.6186 | BQ12: =+Assumption!P260 -> 4091.0261 | BR12: =+Assumption!Q260 -> 4672.9309 | BS12: =+Assumption!R260 -> 4796.573 | BT12: =+Assumption!S260 -> 5368.6066 | BU12: =+Assumption!T260 -> 6042.782 | BV12: =+Assumption!U260 -> 6637.7858 | BW12: =+Assumption!V260 -> 5983.0413 | BX12: =+Assumption!W260 -> 6794.5812 | ... BZ12: =+Assumption!Y260 -> 7807.0885
B13: Gross margin % | C13: =C12/C$7 -> 0.49769393 | D13: =D12/D$7 -> 0.50796225 | E13: =E12/E$7 -> 0.50184399 | F13: =F12/F$7 -> 0.48686565 | G13: =G12/G$7 -> 0.40510969 | H13: =H12/H$7 -> 0.32461019 | I13: =I12/I$7 -> 0.27147707 | J13: =J12/J$7 -> 0.30559214 | ... U13: =U12/U$7 -> 0.45545176 | W13: =W12/W$7 -> 0.34224413 | X13: =X12/X$7 -> 0.29917639 | Y13: =Y12/Y$7 -> 0.28168397 | Z13: =Z12/Z$7 -> 0.34444955 | AA13: =AA12/AA$7 -> 0.15851349 | AB13: =AB12/AB$7 -> 0.38083066 | AC13: =AC12/AC$7 -> 0.25461965 | AD13: =AD12/AD$7 -> 0.27142065 | ... BZ13: =BZ12/BZ$7 -> 0.46602934
B15: Operating expense | C15: =C16+C17+C18+C19 -> 11.332818 | D15: =D16+D17+D18+D19 -> 12.913831 | E15: =E16+E17+E18+E19 -> 20.299495 | F15: =F16+F17+F18+F19 -> 26.722241 | G15: =G16+G17+G18+G19 -> 35.194178 | H15: =H16+H17+H18+H19 -> 40.911796 | I15: =I16+I17+I18+I19 -> 36.656887 | J15: =J16+J17+J18+J19 -> 47.264307 | ... S15: =S16+S17+S18+S19 -> 2640.2498 | T15: =SUMIF($W$3:$BZ$3,T$4,$W15:$BZ15) -> 3112.8343 | U15: =SUMIF($W$3:$BZ$3,U$4,$W15:$BZ15) -> 3605.8216 | W15: =W16+W17+W18+W19 -> 11.258247 | X15: =X16+X17+X18+X19 -> 11.489717 | Y15: =Y16+Y17+Y18+Y19 -> 10.457258 | Z15: =Z16+Z17+Z18+Z19 -> 7.7065744 | AA15: =AA16+AA17+AA18+AA19 -> 8.2691805 | AB15: =AB16+AB17+AB18+AB19 -> 9.6986421 | AC15: =AC16+AC17+AC18+AC19 -> 8.3204128 | AD15: =AD16+AD17+AD18+AD19 -> 10.368652 | ... BZ15: =BZ16+BZ17+BZ18+BZ19 -> 1284.5958
B16: Sales tax | C16: 0 | D16: 0.06298541 | E16: 1.4004868 | F16: 1.099027 | G16: 0.56964762 | H16: 0.82507994 | I16: 1.0701732 | J16: 2.7481565 | K16: 6.4469656 | L16: 10.182498 | M16: 16.597006 | N16: 21.973475 | O16: 21.012073 | P16: =SUMIF($W$3:$BR$3,P$4,$W16:$BR16) -> 62.999788 | Q16: =SUMIF($W$3:$BR$3,Q$4,$W16:$BR16) -> 50.63378 | R16: =SUMIF($W$3:$BR$3,R$4,$W16:$BR16) -> 46.908394 | S16: =SUMIF($W$3:$BR$3,S$4,$W16:$BR16) -> 85.463532 | T16: =SUMIF($W$3:$BZ$3,T$4,$W16:$BZ16) -> 101.16522 | U16: =SUMIF($W$3:$BZ$3,U$4,$W16:$BZ16) -> 122.81877 | W16: 0.55219575 | X16: 0.10853597 | Y16: 0.00229916 | Z16: 0.16204906 | AA16: 0.14487756 | AB16: 0.07281863 | AC16: 0.0283934 | AD16: 0.82408357 | AE16: 0.03186119 | AF16: 0.72010979 | AG16: 0.05195411 | AH16: 1.9442314 | AI16: 0.51099421 | AJ16: 0.92781885 | AK16: 2.2470597 | AL16: 2.7610929 | AM16: 2.3088487 | AN16: 2.5529347 | AO16: 2.7681516 | AP16: 2.5525628 | AQ16: 1.9911661 | AR16: 6.1621618 | AS16: 4.7861507 | AT16: 3.657528 | AU16: 2.9466197 | AV16: 3.916195 | AW16: 5.0707368 | AX16: 10.039923 | AY16: 4.717842 | AZ16: 4.4937591 | BA16: 0.88746472 | BB16: 10.913007 | BC16: 5.8975238 | BD16: 5.8595587 | BE16: 5.542641 | BF16: 45.700065 | BG16: 4.4719719 | BH16: 4.7102712 | BI16: 6.9594304 | BJ16: 34.492107 | BK16: 35.521545 | BL16: -13.935084 | BM16: 11.294864 | BN16: 14.02707 | BO16: 10.625145 | BP16: 34.332624 | BQ16: =BQ$7*BQ80 -> 19.089866 | BR16: =BR$7*BR80 -> 21.415898 | BS16: =BS$7*BS80 -> 21.636037 | BT16: =BT$7*BT80 -> 24.117066 | BU16: =BU$7*BU80 -> 26.557554 | BV16: =BV$7*BV80 -> 28.854567 | BW16: =BW$7*BW80 -> 26.762276 | BX16: =BX$7*BX80 -> 30.251227 | ... BZ16: =BZ$7*BZ80 -> 33.504708
B17: Marketing expense | C17: 2.4544344 | D17: 2.3420214 | E17: 3.0847901 | F17: 3.8827589 | G17: 3.2593719 | H17: 4.6013024 | I17: 3.840157 | J17: 3.6971494 | K17: 32.022266 | L17: 60.233089 | M17: 54.84009 | N17: 106.71352 | O17: 73.036515 | P17: =SUMIF($W$3:$BR$3,P$4,$W17:$BR17) -> 90.729655 | Q17: =SUMIF($W$3:$BR$3,Q$4,$W17:$BR17) -> 124.83987 | R17: =SUMIF($W$3:$BR$3,R$4,$W17:$BR17) -> 199.26812 | S17: =SUMIF($W$3:$BR$3,S$4,$W17:$BR17) -> 235.03778 | T17: =SUMIF($W$3:$BZ$3,T$4,$W17:$BZ17) -> 276 | U17: =SUMIF($W$3:$BZ$3,U$4,$W17:$BZ17) -> 327 | W17: 0.73327105 | X17: 1.0667551 | Y17: 1.5364283 | Z17: 1.264848 | AA17: 0.67469142 | AB17: 1.4096789 | AC17: 1.0156605 | AD17: 0.74012607 | AE17: 1.115911 | AF17: 1.0306053 | AG17: 0.70578328 | AH17: 0.84484985 | AI17: 0.79184657 | AJ17: 0.87935077 | AK17: 16.740203 | AL17: 13.610865 | AM17: 13.991238 | AN17: 13.120208 | AO17: 15.721994 | AP17: 17.399649 | AQ17: 13.217812 | AR17: 11.288367 | AS17: 13.066561 | AT17: 17.267349 | AU17: 14.232697 | AV17: 16.347494 | AW17: 43.276412 | AX17: 32.856912 | AY17: 15.488438 | AZ17: 14.38302 | BA17: 17.745673 | BB17: 25.419384 | BC17: 18.569296 | BD17: 20.622353 | BE17: 30.167126 | BF17: 21.37088 | BG17: 22.253674 | BH17: 21.415118 | BI17: 36.879483 | BJ17: 44.291597 | BK17: 44.826387 | BL17: 44.347236 | BM17: 45.975534 | BN17: 64.118962 | BO17: 50.101678 | BP17: 50.986105 | BQ17: =+Assumption!P278 -> 63.45 | BR17: =+Assumption!Q278 -> 70.5 | BS17: =+Assumption!R278 -> 60.72 | BT17: =+Assumption!S278 -> 63.48 | BU17: =+Assumption!T278 -> 69 | BV17: =+Assumption!U278 -> 82.8 | BW17: =+Assumption!V278 -> 71.94 | BX17: =+Assumption!W278 -> 75.21 | ... BZ17: =+Assumption!Y278 -> 98.1
B18: Administrative expense | C18: 2.3807042 | D18: 3.1882013 | E18: 7.4623433 | F18: 13.732331 | G18: 22.669534 | H18: 28.16479 | I18: 25.248878 | J18: 34.069814 | K18: 116.58222 | L18: 253.34741 | M18: 274.58427 | N18: 370.13664 | O18: 434.16554 | P18: =SUMIF($W$3:$BR$3,P$4,$W18:$BR18) -> 506.80314 | Q18: =SUMIF($W$3:$BR$3,Q$4,$W18:$BR18) -> 433.59245 | R18: =SUMIF($W$3:$BR$3,R$4,$W18:$BR18) -> 679.53645 | S18: =SUMIF($W$3:$BR$3,S$4,$W18:$BR18) -> 726.20985 | T18: =SUMIF($W$3:$BZ$3,T$4,$W18:$BZ18) -> 807 | U18: =SUMIF($W$3:$BZ$3,U$4,$W18:$BZ18) -> 865 | W18: 8.142624 | X18: 8.4842703 | Y18: 7.0883745 | Z18: 4.4495216 | AA18: 5.8251917 | AB18: 6.5917247 | AC18: 5.6519391 | AD18: 7.1800224 | AE18: 8.5104732 | AF18: 9.9425762 | AG18: 6.9774187 | AH18: 8.6393455 | AI18: 7.559295 | AJ18: 8.5351047 | AK18: 65.359824 | AL18: =K18-SUM(AI18:AK18) -> 35.128001 | AM18: 58.470632 | AN18: 66.315122 | AO18: 67.906138 | AP18: 62.967676 | AQ18: 58.167642 | AR18: 60.689629 | AS18: 64.815741 | AT18: 90.911259 | AU18: 72.470847 | AV18: 81.432431 | AW18: 97.284163 | AX18: 118.9492 | AY18: 93.026836 | AZ18: 105.21694 | BA18: 103.77852 | BB18: 132.14325 | BC18: 136.72008 | BD18: 106.51918 | BE18: 136.89125 | BF18: 126.67263 | BG18: 90.76264 | BH18: 96.312496 | BI18: 102.30281 | BJ18: 144.2145 | BK18: 129.26853 | BL18: 177.20631 | BM18: 165.27938 | BN18: 207.78223 | BO18: 148.38785 | BP18: 142.242 | BQ18: =+Assumption!P279 -> 195.26 | BR18: =+Assumption!Q279 -> 240.32 | BS18: =+Assumption!R279 -> 177.54 | BT18: =+Assumption!S279 -> 185.61 | BU18: =+Assumption!T279 -> 201.75 | BV18: =+Assumption!U279 -> 242.1 | BW18: =+Assumption!V279 -> 190.3 | BX18: =+Assumption!W279 -> 198.95 | ... BZ18: =+Assumption!Y279 -> 259.5
B19: R&D | C19: 6.4976791 | D19: 7.3206229 | E19: 8.3518744 | F19: 8.0081239 | G19: 8.6956249 | H19: 7.3206229 | I19: 6.4976791 | J19: 6.7491872 | K19: =SUM(AI19:AL19) -> 129.32626 | L19: 309.4728 | M19: 362.35314 | N19: 506.42898 | O19: 541.09931 | P19: =SUMIF($W$3:$BR$3,P$4,$W19:$BR19) -> 767.01896 | Q19: =SUMIF($W$3:$BR$3,Q$4,$W19:$BR19) -> 739.36758 | R19: =SUMIF($W$3:$BR$3,R$4,$W19:$BR19) -> 1244.0269 | S19: =SUMIF($W$3:$BR$3,S$4,$W19:$BR19) -> 1593.5387 | T19: =SUMIF($W$3:$BZ$3,T$4,$W19:$BZ19) -> 1928.6691 | U19: =SUMIF($W$3:$BZ$3,U$4,$W19:$BZ19) -> 2291.0029 | W19: 1.8301557 | X19: 1.8301557 | Y19: 1.8301557 | Z19: 1.8301557 | AA19: 1.6244198 | AB19: 1.6244198 | AC19: 1.6244198 | AD19: 1.6244198 | AE19: 1.6872968 | AF19: 1.6872968 | AG19: 1.6872968 | AH19: 1.6872968 | AI19: 2 | AJ19: 2 | AK19: 32.326256 | AL19: 93 | AM19: 77.368201 | AN19: 77.368201 | AO19: 80.220011 | AP19: 72.204235 | AQ19: 49.432657 | AR19: 93.978855 | AS19: 81.079602 | AT19: 137.86202 | AU19: 88.009579 | AV19: 87.662414 | AW19: 116.57199 | AX19: 214.185 | AY19: 119.93255 | AZ19: 107.65336 | BA19: 124.63302 | BB19: 188.88037 | BC19: 154.44994 | BD19: 194.57905 | BE19: 211.55509 | BF19: 206.43488 | BG19: 156.38524 | BH19: 166.11044 | BI19: 148.86798 | BJ19: 268.00392 | BK19: 257.38558 | BL19: 267.32643 | BM19: 217.26564 | BN19: 502.04921 | BO19: 290.34105 | BP19: 295.27595 | BQ19: =+Assumption!P280 -> 386.92728 | BR19: =+Assumption!Q280 -> 620.99439 | BS19: =+Assumption!R280 -> 366.44713 | BT19: =+Assumption!S280 -> 385.73382 | BU19: =+Assumption!T280 -> 424.30721 | BV19: =+Assumption!U280 -> 752.18096 | BW19: =+Assumption!V280 -> 435.29055 | BX19: =+Assumption!W280 -> 458.20057 | ... BZ19: =+Assumption!Y280 -> 893.49112
B20: Operating income | C20: =+C12-C15 -> 33.645634 | D20: =+D12-D15 -> 49.843444 | E20: =+E12-E15 -> 61.038965 | F20: =+F12-F15 -> 30.075325 | G20: =+G12-G15 -> 1.4788426 | H20: =+H12-H15 -> -2.3655665 | I20: =+I12-I15 -> -3.6968731 | J20: =+J12-J15 -> -7.0421513 | ... U20: =+U12-U15 -> 24363.191 | W20: =W12-W15 -> 1.8704763 | X20: =X12-X15 -> -5.5586565 | Y20: =Y12-Y15 -> -4.2921627 | Z20: =Z12-Z15 -> 5.6147765 | AA20: =AA12-AA15 -> -5.2276204 | AB20: =AB12-AB15 -> -0.60109657 | AC20: =AC12-AC15 -> -1.6469391 | AD20: =AD12-AD15 -> 3.7787829 | ... BZ20: =BZ12-BZ15 -> 6522.4927
B22: Other income (loss)
B23: Finance cost | C23: =C24+C25 -> 0.4314 | D23: =D24+D25 -> 0.8052 | E23: =E24+E25 -> 0.90568252 | F23: =F24+F25 -> 7.5852688 | G23: =G24+G25 -> 12.762349 | H23: =H24+H25 -> 11.70566 | I23: =I24+I25 -> 6.9046709 | J23: =J24+J25 -> 6.0126569 | ... U23: =U24+U25 -> 80 | W23: =W24+W25 -> 3.0064433 | X23: =X24+X25 -> 3.0064433 | Y23: =Y24+Y25 -> 2.8463865 | Z23: =Z24+Z25 -> 2.8463865 | AA23: =AA24+AA25 -> 2.8703947 | AB23: =AB24+AB25 -> 2.8703947 | AC23: =AC24+AC25 -> 0.5819408 | AD23: =AD24+AD25 -> 0.5819408 | ... BZ23: =BZ24+BZ25 -> 20
B24: Interest income | C24: 0.4314 | D24: 0.8052 | E24: 0.90568252 | F24: 7.5852688 | G24: 12.762349 | H24: 11.70566 | I24: 6.9046709 | J24: 6.0126569 | K24: 3.8327269 | L24: 5.7473989 | M24: 18.132316 | N24: 9.8038459 | O24: 15.721944 | P24: =SUMIF($W$3:$BR$3,P$4,$W24:$BR24) -> 37.571588 | Q24: =SUMIF($W$3:$BR$3,Q$4,$W24:$BR24) -> 104.62682 | R24: =SUMIF($W$3:$BR$3,R$4,$W24:$BR24) -> 108.03043 | S24: =SUMIF($W$3:$BR$3,S$4,$W24:$BR24) -> 190.55613 | T24: =SUMIF($W$3:$BZ$3,T$4,$W24:$BZ24) -> 160 | U24: =SUMIF($W$3:$BZ$3,U$4,$W24:$BZ24) -> 160 | W24: 3.0064433 | X24: 3.0064433 | Y24: 2.8463865 | Z24: 2.8463865 | AA24: 2.8703947 | AB24: 2.8703947 | AC24: 0.5819408 | AD24: 0.5819408 | AE24: 0.40029653 | AF24: 0.40029653 | AG24: 2.6060319 | AH24: 2.6060319 | AI24: 0.098226635 | AJ24: 0.098226635 | AK24: 1.8181368 | AL24: 1.8181368 | AM24: 1.2000018 | AN24: 1.2000018 | AO24: 3.4596026 | AP24: 0 | AQ24: 2.8260327 | AR24: 8.0180394 | AS24: 5.1867575 | AT24: 2.1014867 | AU24: 1.4523238 | AV24: 3.544259 | AW24: 2.1558405 | AX24: 2.6514226 | AY24: 3.0367062 | AZ24: 2.225764 | BA24: 2.1572471 | BB24: 8.3022272 | BC24: 6.2698819 | BD24: 7.3917769 | BE24: 10.946838 | BF24: 12.963092 | BG24: 15.114083 | BH24: 30.854243 | BI24: 29.940874 | BJ24: 28.71762 | BK24: 24.634075 | BL24: 17.35339 | BM24: 37.96675 | BN24: 28.076218 | BO24: 41.677725 | BP24: 68.878409 | BQ24: 40 | BR24: 40 | BS24: 40 | BT24: 40 | BU24: 40 | BV24: 40 | BW24: 40 | BX24: 40 | BY24: 40 | BZ24: 40
B25: Interest expense | C25: 0 | D25: 0 | E25: 0 | F25: 0 | G25: 0 | H25: 0 | I25: 0 | J25: 0 | K25: 0 | L25: -50.25234 | M25: -50.163872 | N25: -61.806144 | O25: -82.987066 | P25: =SUMIF($W$3:$BR$3,P$4,$W25:$BR25) -> -63.360987 | Q25: =SUMIF($W$3:$BR$3,Q$4,$W25:$BR25) -> -54.024538 | R25: =SUMIF($W$3:$BR$3,R$4,$W25:$BR25) -> -53.553118 | S25: =SUMIF($W$3:$BR$3,S$4,$W25:$BR25) -> -73.758301 | T25: =SUMIF($W$3:$BZ$3,T$4,$W25:$BZ25) -> -80 | U25: =SUMIF($W$3:$BZ$3,U$4,$W25:$BZ25) -> -80 | W25: 0 | X25: 0 | Y25: 0 | Z25: 0 | AA25: 0 | AB25: 0 | AC25: 0 | AD25: 0 | AE25: 0 | AF25: 0 | AG25: 0 | AH25: 0 | AI25: 0 | AJ25: 0 | AK25: 0 | AL25: 0 | AM25: 0 | AN25: 0 | AO25: -14.591351 | AP25: -9.0494042 | AQ25: -15.489862 | AR25: -8.7015942 | AS25: -13.151791 | AT25: -12.820625 | AU25: -11.902846 | AV25: -24.81448 | AW25: -13.321954 | AX25: -11.766863 | AY25: -17.062579 | AZ25: -18.817166 | BA25: -24.285847 | BB25: -22.821473 | BC25: -15.849299 | BD25: -14.718377 | BE25: -17.291932 | BF25: -15.50138 | BG25: -15.238871 | BH25: -22.62918 | BI25: -16.156487 | BJ25: 0 | BK25: -13.620137 | BL25: -9.7040147 | BM25: -28.479104 | BN25: -1.7498623 | BO25: -16.715193 | BP25: -17.043109 | BQ25: -20 | BR25: -20 | BS25: -20 | BT25: -20 | BU25: -20 | BV25: -20 | BW25: -20 | BX25: -20 | BY25: -20 | BZ25: -20
B26: Impairement loss | C26: 1.567615 | D26: -0.39454544 | E26: -0.75063602 | F26: -2.4282996 | G26: -2.3239709 | H26: -1.8906766 | I26: -0.27153873 | J26: 0.13126878 | K26: -20.2895 | L26: -66.017827 | M26: 141.65827 | N26: -65.371898 | O26: -82.716344 | P26: =SUMIF($W$3:$BR$3,P$4,$W26:$BR26) -> -339.97956 | Q26: =SUMIF($W$3:$BR$3,Q$4,$W26:$BR26) -> -149.12989 | R26: =SUMIF($W$3:$BR$3,R$4,$W26:$BR26) -> -78.580366 | S26: =SUMIF($W$3:$BR$3,S$4,$W26:$BR26) -> -136.97261 | T26: =SUMIF($W$3:$BZ$3,T$4,$W26:$BZ26) -> -80 | U26: =SUMIF($W$3:$BZ$3,U$4,$W26:$BZ26) -> -80 | W26: 0 | X26: -0.71721864 | Y26: -0.29604331 | Z26: -1.173458 | AA26: 0 | AB26: 0.93464079 | AC26: 0 | AD26: -1.2061795 | AE26: 0 | AF26: 0.47531946 | AG26: 0.44487624 | AH26: -0.78892692 | AI26: 0 | AJ26: -0.78888753 | AK26: -8.8288289 | AL26: -10.671783 | AM26: 0.92495291 | AN26: -2.2734669 | AO26: -20.462011 | AP26: -44.207303 | AQ26: 4.5811823 | AR26: -4.0036553 | AS26: 67.451296 | AT26: 23.156069 | AU26: 0 | AV26: -28.980091 | AW26: -4.0616549 | AX26: -32.093174 | AY26: -0.75715221 | AZ26: -1.5925966 | BA26: -3.0793512 | BB26: -77.287244 | BC26: -2.0350264 | BD26: -23.482999 | BE26: -31.275359 | BF26: -283.18618 | BG26: -3.9609047 | BH26: -28.576053 | BI26: -0.94620838 | BJ26: -115.64672 | BK26: -1.770597 | BL26: -2.6848395 | BM26: -13.653038 | BN26: -60.471892 | BO26: -26.711331 | BP26: -25.261281 | BQ26: -35 | BR26: -50 | BS26: -10 | BT26: -10 | BU26: -10 | BV26: -50 | BW26: -10 | BX26: -10 | BY26: -10 | BZ26: -50
B27: Profit/(loss) on disposal of assets (pre-tax) | C27: 0 | D27: 0 | E27: 0 | F27: 0 | G27: 0 | H27: 0 | I27: 0 | J27: 0 | K27: =SUMIF($W$3:$BB$3,K$4,$W27:$BB27) -> -1.7673325 | L27: =SUMIF($W$3:$BB$3,L$4,$W27:$BB27) -> -0.00245777 | M27: =SUMIF($W$3:$BB$3,M$4,$W27:$BB27) -> -0.13168538 | N27: =SUMIF($W$3:$BB$3,N$4,$W27:$BB27) -> -4.2560443 | O27: =SUMIF($W$3:$BB$3,O$4,$W27:$BB27) -> 2.5290906 | P27: =SUMIF($W$3:$BR$3,P$4,$W27:$BR27) -> 0.19344325 | Q27: =SUMIF($W$3:$BR$3,Q$4,$W27:$BR27) -> -5.7458165 | R27: =SUMIF($W$3:$BR$3,R$4,$W27:$BR27) -> -8.8821038 | S27: =SUMIF($W$3:$BR$3,S$4,$W27:$BR27) -> -6.3379681 | T27: =SUMIF($W$3:$BZ$3,T$4,$W27:$BZ27) -> 0 | U27: =SUMIF($W$3:$BZ$3,U$4,$W27:$BZ27) -> 0 | W27: 0 | X27: 0 | Y27: 0 | Z27: 0 | AA27: 0 | AB27: 0 | AC27: 0 | AD27: 0 | AE27: 0 | AF27: 0 | AG27: 0 | AH27: =J27-SUM(AE27:AG27) -> 0 | AI27: 0 | AJ27: 0 | AK27: 0 | AL27: -1.7673325 | AM27: 0 | AN27: -0.00245777 | AO27: 0 | AP27: 0 | AQ27: -0.01598569 | AR27: 0 | AS27: 0.01010615 | AT27: -0.12580584 | AU27: -0.01577185 | AV27: 0.0095409 | AW27: 0.0644887 | AX27: -4.314302 | AY27: 3.2194994 | AZ27: -0.66556457 | BA27: 0.09718759 | BB27: -0.12203179 | BC27: -0.01735809 | BD27: 0.02454729 | BE27: -0.06699709 | BF27: 0.25325114 | BG27: 0 | BH27: 0.87451131 | BI27: -0.51025372 | BJ27: -6.1100741 | BK27: -0.09378976 | BL27: -6.6950293 | BM27: 0.94546299 | BN27: -3.0387477 | BO27: -3.1270358 | BP27: -3.2109323 | BQ27: 0 | BR27: 0 | BS27: 0 | BT27: 0 | BU27: 0 | BV27: 0 | BW27: 0 | BX27: 0 | BY27: 0 | BZ27: 0
B28: Foreign exchange gain/(loss) | C28: -0.4794046 | D28: -1.5433853 | E28: -3.0584846 | F28: -3.9351954 | G28: -10.060272 | H28: -7.4208825 | I28: -3.9263415 | J28: -4.9062542 | K28: -40.959178 | L28: -34.708512 | M28: 14.954346 | N28: -11.935535 | O28: -16.547993 | P28: =SUMIF($W$3:$BR$3,P$4,$W28:$BR28) -> 47.990243 | Q28: =SUMIF($W$3:$BR$3,Q$4,$W28:$BR28) -> 32.967905 | R28: =SUMIF($W$3:$BR$3,R$4,$W28:$BR28) -> 89.953837 | S28: =SUMIF($W$3:$BR$3,S$4,$W28:$BR28) -> -37.4441 | T28: =SUMIF($W$3:$BZ$3,T$4,$W28:$BZ28) -> 0 | U28: =SUMIF($W$3:$BZ$3,U$4,$W28:$BZ28) -> 0 | W28: -2.5313556 | X28: -5.3889413 | Y28: -6.3544988 | Z28: 4.6591015 | AA28: -1.3591176 | AB28: -3.2503101 | AC28: -1.2995528 | AD28: 1.933039 | AE28: 0.26398918 | AF28: -0.28985981 | AG28: -2.1083951 | AH28: -2.7719885 | AI28: 0.24498405 | AJ28: 0.57927363 | AK28: -22.439101 | AL28: -19.344335 | AM28: -34.788586 | AN28: -19.557479 | AO28: -1.5252973 | AP28: -5.5609415 | AQ28: -1.3150042 | AR28: 5.0708227 | AS28: 16.497568 | AT28: -5.2990407 | AU28: 6.5781706 | AV28: -6.0780315 | AW28: 8.6274449 | AX28: -21.063119 | AY28: -2.6280031 | AZ28: -5.2522157 | BA28: 2.1433355 | BB28: -10.81111 | BC28: -10.024343 | BD28: 46.17252 | BE28: 25.956611 | BF28: -14.114546 | BG28: -16.36203 | BH28: 64.931908 | BI28: -8.4609244 | BJ28: -7.1410489 | BK28: 14.462298 | BL28: 32.517495 | BM28: -82.418831 | BN28: 125.39287 | BO28: -7.6687683 | BP28: -29.775332 | BQ28: 0 | BR28: 0 | BS28: 0 | BT28: 0 | BU28: 0 | BV28: 0 | BW28: 0 | BX28: 0 | BY28: 0 | BZ28: 0
B29: Income (loss) from associates | C29: 0 | D29: 0 | E29: 0 | F29: 0 | G29: 0 | H29: =SUMIF($W$3:$BB$3,H$4,$W29:$BB29) -> 0 | I29: =SUMIF($W$3:$BB$3,I$4,$W29:$BB29) -> 0 | J29: =SUMIF($W$3:$BB$3,J$4,$W29:$BB29) -> 0 | K29: =SUMIF($W$3:$BB$3,K$4,$W29:$BB29) -> 0 | L29: =SUMIF($W$3:$BB$3,L$4,$W29:$BB29) -> 5.0666752 | M29: =SUMIF($W$3:$BB$3,M$4,$W29:$BB29) -> 53.448619 | N29: =SUMIF($W$3:$BB$3,N$4,$W29:$BB29) -> 209.35382 | O29: =SUMIF($W$3:$BB$3,O$4,$W29:$BB29) -> 62.776311 | P29: =SUMIF($W$3:$BR$3,P$4,$W29:$BR29) -> 72.518985 | Q29: =SUMIF($W$3:$BR$3,Q$4,$W29:$BR29) -> 294.23791 | R29: =SUMIF($W$3:$BR$3,R$4,$W29:$BR29) -> -45.685118 | S29: =SUMIF($W$3:$BR$3,S$4,$W29:$BR29) -> 58.68665 | T29: =SUMIF($W$3:$BZ$3,T$4,$W29:$BZ29) -> 0 | U29: =SUMIF($W$3:$BZ$3,U$4,$W29:$BZ29) -> 0 | W29: 0 | X29: 0 | Y29: 0 | Z29: 0 | AA29: 0 | AB29: 0 | AC29: 0 | AD29: 0 | AE29: 0 | AF29: 0 | AG29: 0 | AH29: 0 | AI29: 0 | AJ29: 0 | AK29: 0 | AL29: 0 | AM29: 0 | AN29: 0 | AO29: 0 | AP29: 5.0666752 | AQ29: 1.6457945 | AR29: 0 | AS29: 0.87104401 | AT29: 50.931781 | AU29: 0 | AV29: 0 | AW29: 0 | AX29: 209.35382 | AY29: 0 | AZ29: 30.700322 | BA29: 0 | BB29: 32.07599 | BC29: 0 | BD29: 0.04120373 | BE29: 0.79594674 | BF29: 71.681835 | BG29: 0 | BH29: 1.71 | BI29: 4.3881 | BJ29: 288.13981 | BK29: 0 | BL29: 1.0332576 | BM29: 0 | BN29: -46.718376 | BO29: 19.141743 | BP29: 39.544907 | BQ29: 0 | BR29: 0 | BS29: 0 | BT29: 0 | BU29: 0 | BV29: 0 | BW29: 0 | BX29: 0 | BY29: 0 | BZ29: 0
B30: Share of results in jointly controlled entities | C30: 0 | D30: 0 | E30: 0 | F30: 0 | G30: 0 | H30: 0 | I30: 0 | J30: 0 | K30: 0 | L30: 0 | M30: 0 | N30: 0 | O30: 0 | P30: =SUMIF($W$3:$BR$3,P$4,$W30:$BR30) -> 0 | Q30: =SUMIF($W$3:$BR$3,Q$4,$W30:$BR30) -> 2 | R30: =SUMIF($W$3:$BR$3,R$4,$W30:$BR30) -> 9 | S30: =SUMIF($W$3:$BR$3,S$4,$W30:$BR30) -> 6 | T30: =SUMIF($W$3:$BZ$3,T$4,$W30:$BZ30) -> 0 | U30: =SUMIF($W$3:$BZ$3,U$4,$W30:$BZ30) -> 0 | W30: 0 | X30: 0 | Y30: 0 | Z30: 0 | AA30: 0 | AB30: 0 | AC30: 0 | AD30: 0 | AE30: 0 | AF30: 0 | AG30: 0 | AH30: 0 | AI30: 0 | AJ30: 0 | AK30: 0 | AL30: 0 | AM30: 0 | AN30: 0 | AO30: 0 | AP30: 0 | AQ30: 0 | AR30: 0 | AS30: 0 | AT30: 0 | AU30: 0 | AV30: 0 | AW30: 0 | AX30: 0 | AY30: 0 | AZ30: 0 | BA30: 0 | BB30: 0 | BC30: 0 | BD30: 0 | BE30: 0 | BF30: 0 | BG30: 0 | BH30: 0 | BI30: 1 | BJ30: 1 | BK30: 1 | BL30: 2 | BM30: 3 | BN30: 3 | BO30: 3 | BP30: 3 | BQ30: 0 | BR30: 0 | BS30: 0 | BT30: 0 | BU30: 0 | BV30: 0 | BW30: 0 | BX30: 0 | BY30: 0 | BZ30: 0
B31: Other non-operating income/expense | C31: =+C32-C23-C26-C27-C29-C30-C28 -> 0.26656564 | D31: =+D32-D23-D26-D27-D29-D30-D28 -> 0.2254469 | E31: =+E32-E23-E26-E27-E29-E30-E28 -> 1.5631601 | F31: =+F32-F23-F26-F27-F29-F30-F28 -> 2.3436417 | G31: =+G32-G23-G26-G27-G29-G30-G28 -> 14.355195 | H31: =+H32-H23-H26-H27-H29-H30-H28 -> 6.3347259 | I31: =+I32-I23-I26-I27-I29-I30-I28 -> 7.31333 | J31: =+J32-J23-J26-J27-J29-J30-J28 -> 16.715341 | ... O31: =+O32-O23-O26-O27-O29-O30-O28 -> 162.44787 | P31: =SUMIF($W$3:$BR$3,P$4,$W31:$BR31) -> 197.96603 | Q31: =SUMIF($W$3:$BR$3,Q$4,$W31:$BR31) -> 79.857533 | R31: =SUMIF($W$3:$BR$3,R$4,$W31:$BR31) -> 135.30049 | S31: =SUMIF($W$3:$BR$3,S$4,$W31:$BR31) -> 71.593122 | T31: =SUMIF($W$3:$BZ$3,T$4,$W31:$BZ31) -> 63 | U31: =SUMIF($W$3:$BZ$3,U$4,$W31:$BZ31) -> 116.15217 | W31: =+W32-W23-W26-W27-W29-W30-W28 -> 3.1096156 | X31: =+X32-X23-X26-X27-X29-X30-X28 -> 0.12677372 | Y31: =+Y32-Y23-Y26-Y27-Y29-Y30-Y28 -> 12.816932 | Z31: =+Z32-Z23-Z26-Z27-Z29-Z30-Z28 -> -7.2277408 | AA31: =+AA32-AA23-AA26-AA27-AA29-AA30-AA28 -> -0.11691668 | AB31: =+AB32-AB23-AB26-AB27-AB29-AB30-AB28 -> -1.2252309 | AC31: =+AC32-AC23-AC26-AC27-AC29-AC30-AC28 -> 2.0992708 | AD31: =+AD32-AD23-AD26-AD27-AD29-AD30-AD28 -> 6.6058068 | ... BP31: =+BP32-BP23-BP26-BP27-BP29-BP30-BP28 -> 11.440948 | BQ31: 11 | BR31: 19 | BS31: 15 | BT31: 15 | BU31: 15 | BV31: 18 | BW31: 30.152174 | BX31: 30 | BY31: 30 | BZ31: 26
B32: Other income (loss) | C32: =+C33-C20 -> 1.786176 | D32: =+D33-D20 -> -0.90728387 | E32: =+E33-E20 -> -1.3402781 | F32: =+F33-F20 -> 3.5654155 | G32: =+G33-G20 -> 14.733301 | H32: =+H33-H20 -> 8.7288263 | I32: =+I33-I20 -> 10.020121 | J32: =+J33-J20 -> 17.953013 | ... O32: =+O33-O20 -> 61.223817 | P32: =SUM(P24:P31) -> -47.100259 | Q32: =SUM(Q24:Q31) -> 304.78992 | R32: =SUM(R24:R31) -> 155.58405 | S32: =SUM(S24:S31) -> 72.322925 | T32: =SUM(T24:T31) -> 63 | U32: =SUM(U24:U31) -> 116.15217 | W32: =+W33-W20 -> 3.5847033 | X32: =+X33-X20 -> -2.9729429 | Y32: =+Y33-Y20 -> 9.0127767 | Z32: =+Z33-Z20 -> -0.89571079 | AA32: =+AA33-AA20 -> 1.3943604 | AB32: =+AB33-AB20 -> -0.67050549 | AC32: =+AC33-AC20 -> 1.3816588 | AD32: =+AD33-AD20 -> 7.914607 | ... BP32: =+BP33-BP20 -> 47.57361 | BQ32: =SUM(BQ24:BQ31) -> -4 | BR32: =SUM(BR24:BR31) -> -11 | BS32: =SUM(BS24:BS31) -> 25 | BT32: =SUM(BT24:BT31) -> 25 | BU32: =SUM(BU24:BU31) -> 25 | BV32: =SUM(BV24:BV31) -> -12 | BW32: =SUM(BW24:BW31) -> 40.152174 | BX32: =SUM(BX24:BX31) -> 40 | ... BZ32: =SUM(BZ24:BZ31) -> -4
B33: Pre-tax profit | C33: 35.43181 | D33: 48.936161 | E33: 59.698687 | F33: 33.64074 | G33: 16.212143 | H33: =SUM(W33:Z33) -> 6.3632598 | I33: =SUM(AA33:AD33) -> 6.3232475 | J33: 10.910862 | K33: =SUM(AI33:AL33) -> 205.89282 | L33: 694.95248 | M33: 576.67677 | N33: 986.95919 | O33: 959.91532 | P33: =P20+P32 -> 1351.5513 | Q33: =Q20+Q32 -> 2492.4634 | R33: =R20+R32 -> 6052.4374 | S33: =S20+S32 -> 12012.138 | T33: =T20+T32 -> 19795.913 | U33: =U20+U32 -> 24479.343 | W33: 5.4551796 | X33: -8.5315994 | Y33: 4.7206139 | Z33: 4.7190657 | AA33: -3.8332601 | AB33: -1.2716021 | AC33: -0.26528028 | AD33: 11.69339 | AE33: -6.4971679 | AF33: 12.787396 | AG33: -1.6313039 | AH33: 6.251937 | AI33: -4.3815274 | AJ33: 8.7629566 | AK33: 144.81164 | AL33: 56.699752 | AM33: 168.59379 | AN33: 198.18916 | AO33: 183.29088 | AP33: 144.87865 | AQ33: 117.04086 | AR33: 115.13951 | AS33: 156.96568 | AT33: 187.53072 | AU33: 171.22008 | AV33: 257.76848 | AW33: 268.8283 | AX33: 289.14233 | AY33: 147.2281 | AZ33: 222.75426 | BA33: 242.13319 | BB33: 347.79977 | BC33: 233.26123 | BD33: 290.03491 | BE33: 409.13812 | BF33: 419.11702 | BG33: 270.0942 | BH33: 444.20014 | BI33: 754.71227 | BJ33: 1023.4567 | BK33: 1175.334 | BL33: 1554.1839 | BM33: 1683.1363 | BN33: 1639.7832 | BO33: 1989.783 | BP33: 2891.3555 | BQ33: =BQ20+BQ32 -> 3422.299 | BR33: =BR20+BR32 -> 3708.7006 | BS33: =BS20+BS32 -> 4195.2299 | BT33: =BT20+BT32 -> 4734.6658 | BU33: =BU20+BU32 -> 5346.1672 | BV33: =BV20+BV32 -> 5519.8503 | BW33: =BW20+BW32 -> 5298.9007 | BX33: =BX20+BX32 -> 6071.9694 | ... BZ33: =BZ20+BZ32 -> 6518.4927
B34: Check | C34: =+C12-C15+C32-C33 -> 0 | D34: =+D12-D15+D32-D33 -> 0 | E34: =+E12-E15+E32-E33 -> 0 | F34: =+F12-F15+F32-F33 -> 0 | G34: =+G12-G15+G32-G33 -> 0 | H34: =+H12-H15+H32-H33 -> 0 | I34: =+I12-I15+I32-I33 -> 0 | J34: =+J12-J15+J32-J33 -> 0 | ... U34: =+U12-U15+U32-U33 -> 0 | W34: =+W12-W15+W32-W33 -> 0 | X34: =+X12-X15+X32-X33 -> 0 | Y34: =+Y12-Y15+Y32-Y33 -> 0 | Z34: =+Z12-Z15+Z32-Z33 -> 0 | AA34: =+AA12-AA15+AA32-AA33 -> 0 | AB34: =+AB12-AB15+AB32-AB33 -> 0 | AC34: =+AC12-AC15+AC32-AC33 -> 0 | AD34: =+AD12-AD15+AD32-AD33 -> 0 | ... BR34: =+BR12-BR15+BR32-BR33 -> 0
B36: Income taxes | C36: 4.1602532 | D36: 7.0203088 | E36: 8.4882779 | F36: 4.8648626 | G36: 1.9712163 | H36: 0.50694349 | I36: 0.77887854 | J36: 0.85673003 | K36: 44.387407 | L36: 71.836498 | M36: 63.189572 | N36: 110.53494 | O36: 73.41867 | P36: =SUMIF($W$3:$BR$3,P$4,$W36:$BR36) -> 117.86204 | Q36: =SUMIF($W$3:$BR$3,Q$4,$W36:$BR36) -> 284.8132 | R36: =SUMIF($W$3:$BR$3,R$4,$W36:$BR36) -> 680.66223 | S36: =SUMIF($W$3:$BR$3,S$4,$W36:$BR36) -> 1494.401 | T36: =SUMIF($W$3:$BZ$3,T$4,$W36:$BZ36) -> 2375.5096 | U36: =SUMIF($W$3:$BZ$3,U$4,$W36:$BZ36) -> 2937.5211 | W36: 0.81827694 | X36: -0.90110974 | Y36: 0.70809209 | Z36: -0.01565628 | AA36: 0 | AB36: 0 | AC36: 0 | AD36: 0.77887854 | AE36: 0 | AF36: 0.96845216 | AG36: -0.45922029 | AH36: 0.34749816 | AI36: 0 | AJ36: 0.41265871 | AK36: 22.476526 | AL36: 21.498222 | AM36: 20.827133 | AN36: 29.051968 | AO36: 18.721022 | AP36: 3.2363751 | AQ36: 17.540925 | AR36: 7.3253887 | AS36: 6.3952057 | AT36: 31.928052 | AU36: 17.558211 | AV36: 45.283206 | AW36: 30.688738 | AX36: 17.004789 | AY36: 12.251967 | AZ36: 12.460759 | BA36: 21.706855 | BB36: 26.999089 | BC36: 17.961131 | BD36: 15.689839 | BE36: 47.86208 | BF36: 36.348992 | BG36: 25.505658 | BH36: 41.668273 | BI36: 89.529402 | BJ36: 128.10986 | BK36: 147.63652 | BL36: 174.95993 | BM36: 218.4883 | BN36: 139.57748 | BO36: 299.26768 | BP36: 339.41335 | BQ36: =+BQ89*BQ33 -> 410.67588 | BR36: =+BR89*BR33 -> 445.04408 | BS36: =+BS89*BS33 -> 503.42758 | BT36: =+BT89*BT33 -> 568.15989 | BU36: =+BU89*BU33 -> 641.54006 | BV36: =+BV89*BV33 -> 662.38204 | BW36: =+BW89*BW33 -> 635.86808 | BX36: =+BX89*BX33 -> 728.63633 | ... BZ36: =+BZ89*BZ33 -> 782.21912
B37: Minority interest | C37: =+C33-C36-C40 -> 0 | D37: =+D33-D36-D40 -> 0 | E37: =+E33-E36-E40 -> 0 | F37: =+F33-F36-F40 -> 0 | G37: =+G33-G36-G40 -> 0 | H37: =+H33-H36-H40 -> 0.10265952 | I37: =+I33-I36-I40 -> 0 | J37: =+J33-J36-J40 -> 0 | ... O37: =+O33-O36-O40 -> 9.5195194 | P37: =SUMIF($W$3:$BR$3,P$4,$W37:$BR37) -> 9.6983767 | Q37: =SUMIF($W$3:$BR$3,Q$4,$W37:$BR37) -> 34.122409 | R37: =SUMIF($W$3:$BR$3,R$4,$W37:$BR37) -> 200.28917 | S37: =SUMIF($W$3:$BR$3,S$4,$W37:$BR37) -> 623.85889 | T37: =SUMIF($W$3:$BZ$3,T$4,$W37:$BZ37) -> 889.90631 | U37: =SUMIF($W$3:$BZ$3,U$4,$W37:$BZ37) -> 1052.587 | W37: =+W33-W36-W40 -> 0 | X37: =+X33-X36-X40 -> 0 | Y37: =+Y33-Y36-Y40 -> 0 | Z37: =+Z33-Z36-Z40 -> 0 | AA37: =+AA33-AA36-AA40 -> 0 | AB37: =+AB33-AB36-AB40 -> 0 | AC37: =+AC33-AC36-AC40 -> 0 | AD37: =+AD33-AD36-AD40 -> 0 | ... AN37: =+AN33-AN36-AN40 -> 0 | AO37: =+AO33-AO36-AO40-AO38-AO39 -> 0 | AP37: =+AP33-AP36-AP40-AP38-AP39 -> -2.8421709e-14 | AQ37: =+AQ33-AQ36-AQ40-AQ38-AQ39 -> -1.4210855e-14 | AR37: =+AR33-AR36-AR40-AR38-AR39 -> -1.4210855e-14 | AS37: =+AS33-AS36-AS40-AS38-AS39 -> 0 | AT37: =+AT33-AT36-AT40-AT38-AT39 -> -2.8421709e-14 | AU37: =+AU33-AU36-AU40-AU38-AU39 -> -2.8421709e-14 | AV37: =+AV33-AV36-AV40-AV38-AV39 -> 1.006929 | ... BP37: =+BP33-BP36-BP40-BP38-BP39 -> 139.70288 | BQ37: =+(BQ33-BQ36)*0.06 -> 180.69739 | BR37: =+(BR33-BR36)*0.06 -> 195.81939 | BS37: =+Assumption!R379 -> 188.70838 | BT37: =+Assumption!S379 -> 211.60842 | BU37: =+Assumption!T379 -> 234.32999 | BV37: =+Assumption!U379 -> 255.25953 | BW37: =+Assumption!V379 -> 236.56778 | BX37: =+Assumption!W379 -> 268.43237 | BY37: =+Assumption!X379 -> 274.58679 | BZ37: =+Assumption!Y379 -> 273.0001
B38: Preferred dividends | C38: 0 | D38: 0 | E38: 0 | F38: 0 | G38: 0 | H38: 0 | I38: 0 | J38: 0 | K38: =+K12/J12-1 -> 14.702158 | L38: =+L12/K12-1 -> 1.2267283 | M38: =+M12/L12-1 -> -0.082798449 | N38: 0 | O38: 0 | P38: =SUMIF($W$3:$BR$3,P$4,$W38:$BR38) -> 0 | Q38: =SUMIF($W$3:$BR$3,Q$4,$W38:$BR38) -> 0 | R38: =SUMIF($W$3:$BR$3,R$4,$W38:$BR38) -> 0 | S38: =SUMIF($W$3:$BR$3,S$4,$W38:$BR38) -> 0 | T38: =SUMIF($W$3:$BZ$3,T$4,$W38:$BZ38) -> 0 | U38: =SUMIF($W$3:$BZ$3,U$4,$W38:$BZ38) -> 0 | AI38: 0 | AJ38: 0 | AK38: 0 | AL38: 0 | AM38: 0 | AN38: 0 | AO38: 0 | AP38: 0 | AQ38: 0 | AR38: 0 | AS38: 0 | AT38: 0 | AU38: 0 | AV38: 0 | AW38: 0 | AX38: 0 | AY38: 0 | AZ38: 0 | BA38: 0 | BB38: 0 | BC38: 0 | BD38: 0 | BE38: 0 | BF38: 0 | BG38: 0 | BH38: 0 | BI38: 0 | BJ38: 0 | BK38: 0 | BL38: 0 | BM38: 0 | BN38: 0 | BO38: 0 | BP38: 0 | BQ38: 0 | BR38: 0 | BS38: 0 | BT38: 0 | BU38: 0 | BV38: 0 | BW38: 0 | BX38: 0 | BY38: 0 | BZ38: 0
B39: Extraordinary gain/(loss) | C39: 0 | D39: 0 | E39: 0 | F39: 0 | G39: 0 | H39: 0 | I39: 0 | J39: 0 | K39: 0 | L39: 0 | M39: 0 | N39: 0 | O39: 0 | P39: =SUMIF($W$3:$BR$3,P$4,$W39:$BR39) -> 0 | Q39: =SUMIF($W$3:$BR$3,Q$4,$W39:$BR39) -> 0 | R39: =SUMIF($W$3:$BR$3,R$4,$W39:$BR39) -> 0 | S39: =SUMIF($W$3:$BR$3,S$4,$W39:$BR39) -> 0 | T39: =SUMIF($W$3:$BZ$3,T$4,$W39:$BZ39) -> 0 | U39: =SUMIF($W$3:$BZ$3,U$4,$W39:$BZ39) -> 0 | AI39: 0 | AJ39: 0 | AK39: 0 | AL39: 0 | AM39: 0 | AN39: 0 | AO39: 0 | AP39: 0 | AQ39: 0 | AR39: 0 | AS39: 0 | AT39: 0 | AU39: 0 | AV39: 0 | AW39: 0 | AX39: 0 | AY39: 0 | AZ39: 0 | BA39: 0 | BB39: 0 | BC39: 0 | BD39: 0 | BE39: 0 | BF39: 0 | BG39: 0 | BH39: 0 | BI39: 0 | BJ39: 0 | BK39: 0 | BL39: 0 | BM39: 0 | BN39: 0 | BO39: 0 | BP39: 0 | BQ39: 0 | BR39: 0 | BS39: 0 | BT39: 0 | BU39: 0 | BV39: 0 | BW39: 0 | BX39: 0 | BY39: 0 | BZ39: 0
B40: Net income | C40: 31.271556 | D40: 41.915852 | E40: 51.210409 | F40: 28.775878 | G40: 14.240927 | H40: =SUM(W40:Z40) -> 5.7536568 | I40: =SUM(AA40:AD40) -> 5.544369 | J40: 10.054132 | K40: =SUM(AI40:AL40) -> 161.50542 | L40: 623.11598 | M40: 513.4872 | N40: 865.48355 | O40: 876.97713 | P40: =+P33-P36-P37-P38+P39 -> 1223.9909 | Q40: =+Q33-Q36-Q37-Q38+Q39 -> 2173.5277 | R40: =+R33-R36-R37-R38+R39 -> 5171.486 | S40: =+S33-S36-S37-S38+S39 -> 9893.8783 | T40: =+T33-T36-T37-T38+T39 -> 16530.497 | U40: =+U33-U36-U37-U38+U39 -> 20489.235 | W40: 4.6369027 | X40: -7.6304896 | Y40: 4.0125218 | Z40: 4.7347219 | AA40: -3.8332601 | AB40: -1.2716021 | AC40: -0.26528028 | AD40: 10.914511 | AE40: -6.4971679 | AF40: 11.818944 | AG40: -1.1720836 | AH40: 5.9044388 | AI40: -4.3815274 | AJ40: 8.3502979 | AK40: 122.33512 | AL40: 35.20153 | AM40: 147.76666 | AN40: 169.13719 | AO40: 164.56986 | AP40: 141.64227 | AQ40: 99.499939 | AR40: 107.81412 | AS40: 150.57048 | AT40: 155.60266 | AU40: 153.66187 | AV40: 211.47835 | AW40: 234.73558 | AX40: 265.60775 | AY40: 133.0697 | AZ40: 207.75126 | BA40: 219.2824 | BB40: 316.87377 | BC40: 217.4126 | BD40: 275.04257 | BE40: 360.05326 | BF40: 371.48243 | BG40: 249.92027 | BH40: 363.83251 | BI40: 682.1151 | BJ40: 877.65987 | BK40: 1009.2663 | BL40: 1349.1548 | BM40: 1394.2381 | BN40: 1418.8268 | BO40: 1582.8761 | BP40: 2412.2393 | BQ40: =+BQ33-BQ36-BQ37-BQ38+BQ39 -> 2830.9257 | BR40: =+BR33-BR36-BR37-BR38+BR39 -> 3067.8372 | BS40: =+BS33-BS36-BS37-BS38+BS39 -> 3503.0939 | BT40: =+BT33-BT36-BT37-BT38+BT39 -> 3954.8974 | BU40: =+BU33-BU36-BU37-BU38+BU39 -> 4470.2972 | BV40: =+BV33-BV36-BV37-BV38+BV39 -> 4602.2087 | BW40: =+BW33-BW36-BW37-BW38+BW39 -> 4426.4648 | BX40: =+BX33-BX36-BX37-BX38+BX39 -> 5074.9007 | ... BZ40: =+BZ33-BZ36-BZ37-BZ38+BZ39 -> 5463.2734
B41: Check | C41: =+C33-C36-C37-C40 -> 0 | D41: =+D33-D36-D37-D40 -> 0 | E41: =+E33-E36-E37-E40 -> 0 | F41: =+F33-F36-F37-F40 -> 0 | G41: =+G33-G36-G37-G40 -> 0 | H41: =+H33-H36-H37-H40 -> 0 | I41: =+I33-I36-I37-I40 -> 0 | J41: =+J33-J36-J37-J40 -> 0 | ... U41: =+U33-U36-U37-U40 -> 0 | AI41: =+AI33-AI36-AI37-AI40 -> 0 | AJ41: =+AJ33-AJ36-AJ37-AJ40 -> 0 | AK41: =+AK33-AK36-AK37-AK40 -> 0 | AL41: =+AL33-AL36-AL37-AL40 -> 0 | AM41: =+AM33-AM36-AM37-AM40 -> 0 | AN41: =+AN33-AN36-AN37-AN40 -> 0 | AO41: =+AO33-AO36-AO37-AO40 -> 0 | AP41: =+AP33-AP36-AP37-AP40 -> 0 | ... BZ41: =+BZ33-BZ36-BZ37-BZ40 -> 0
B43: Minority as % of net profit | BC43: =+BC37/(BC33-BC36) -> -0.0098118981 | BD43: =+BD37/(BD33-BD36) -> -0.0025424227 | BE43: =+BE37/(BE33-BE36) -> 0.0033846103 | BF43: =+BF37/(BF33-BF36) -> 0.029484181 | BG43: =+BG37/(BG33-BG36) -> -0.021798785 | BH43: =+BH37/(BH33-BH36) -> 0.096139869 | BI43: =+BI37/(BI33-BI36) -> -0.02545501 | BJ43: =+BJ37/(BJ33-BJ36) -> 0.019754373 | ... BZ43: =+BZ37/(BZ33-BZ36) -> 0.047591891
B45: EBIT | C45: =+C20 -> 33.645634 | D45: =+D20 -> 49.843444 | E45: =+E20 -> 61.038965 | F45: =+F20 -> 30.075325 | G45: =+G20 -> 1.4788426 | H45: =+H20 -> -2.3655665 | I45: =+I20 -> -3.6968731 | J45: =+J20 -> -7.0421513 | ... U45: =+U20 -> 24363.191 | W45: =+W20 -> 1.8704763 | X45: =+X20 -> -5.5586565 | Y45: =+Y20 -> -4.2921627 | Z45: =+Z20 -> 5.6147765 | AA45: =+AA20 -> -5.2276204 | AB45: =+AB20 -> -0.60109657 | AC45: =+AC20 -> -1.6469391 | AD45: =+AD20 -> 3.7787829 | ... BZ45: =+BZ20 -> 6522.4927
B46: Depreciation | C46: 1.9408838 | D46: 3.9522376 | E46: 6.3353015 | F46: 8.994307 | G46: 11.870318 | H46: 12.538386 | I46: 15.11947 | J46: 18.808306 | K46: 60.37121 | L46: 130.24076 | M46: 172.48206 | N46: 250.66216 | O46: 320.64924 | P46: 361.31217 | Q46: =+Q179 -> 384.59687 | R46: =+R179 -> 545.14848 | S46: =+S179 -> 640.187 | T46: =+T179 -> 893.09919 | U46: =+U179 -> 1080.3578 | W46: 2.9944527 | X46: 2.9944527 | Y46: 3.2747401 | Z46: 3.2747401 | AA46: 3.6350838 | AB46: 3.6350838 | AC46: 3.9246514 | AD46: 3.9246514 | AE46: 2.4186165 | AF46: 2.4186165 | AG46: 6.9855367 | AH46: 6.9855367 | AI46: 4.8081469 | AJ46: 4.8081469 | AK46: 25.377458 | AL46: 25.377458 | AM46: 29.567363 | AN46: 29.567363 | AO46: 35.553018 | AP46: 35.553018 | AQ46: 39.186095 | AR46: 39.186095 | AS46: 47.054933 | AT46: 47.054933 | AU46: 56.4832 | AV46: 56.4832 | AW46: 68.847881 | AX46: 68.847881 | AY46: 77.122581 | AZ46: 77.122581 | BA46: 83.202039 | BB46: 83.202039 | BC46: 87.298491 | BD46: 87.298491 | BE46: 93.357593 | BF46: 93.357593 | BG46: =+$Q$46/4 -> 96.149217 | BH46: =+$Q$46/4 -> 96.149217 | BI46: =+$Q$46/4 -> 96.149217 | BJ46: =+$Q$46/4 -> 96.149217 | BK46: =+$R$46/4 -> 136.28712 | BL46: =+$R$46/4 -> 136.28712 | BM46: =+$R$46/4 -> 136.28712 | BN46: =+$R$46/4 -> 136.28712 | BO46: =+$S$46/4 -> 160.04675 | BP46: =+$S$46/4 -> 160.04675 | BQ46: =+$S$46/4 -> 160.04675 | BR46: =+$S$46/4 -> 160.04675 | BS46: =+$T$46/4 -> 223.2748 | BT46: =+$T$46/4 -> 223.2748 | BU46: =+$T$46/4 -> 223.2748 | BV46: =+$T$46/4 -> 223.2748 | BW46: =+$U$46/4 -> 270.08944 | BX46: =+$U$46/4 -> 270.08944 | BY46: =+$U$46/4 -> 270.08944 | BZ46: =+$U$46/4 -> 270.08944
B47: Amortization | C47: 0.11056381 | D47: 0.29378618 | E47: 0.62512884 | F47: 0.63826525 | G47: 8.4850257 | H47: 12.380054 | I47: 12.263715 | J47: 12.265049 | K47: 40.980841 | L47: 71.075269 | M47: 68.808505 | N47: 80.367939 | O47: 85.874897 | P47: 83.428534 | Q47: =+Q187 -> 85.462292 | R47: =+R187 -> 98.327096 | S47: =+S187 -> 90.655063 | T47: =+T187 -> 76.097848 | U47: =+U187 -> 65.034364 | W47: 3.0969504 | X47: 3.0969504 | Y47: 3.0930767 | Z47: 3.0930767 | AA47: 3.0630875 | AB47: 3.0630875 | AC47: 3.0687698 | AD47: 3.0687698 | AE47: 3.0737646 | AF47: 3.0737646 | AG47: 3.0587601 | AH47: 3.0587601 | AI47: 3.0791833 | AJ47: 3.0791833 | AK47: 17.411237 | AL47: 17.411237 | AM47: 17.721112 | AN47: 17.721112 | AO47: 17.816522 | AP47: 17.816522 | AQ47: 17.575764 | AR47: 17.575764 | AS47: 16.828489 | AT47: 16.828489 | AU47: 18.924339 | AV47: 18.924339 | AW47: 21.25963 | AX47: 21.25963 | AY47: 20.972787 | AZ47: 20.972787 | BA47: 21.964662 | BB47: 21.964662 | BC47: 20.711653 | BD47: 20.711653 | BE47: 21.002614 | BF47: 21.002614 | BG47: =+$Q$47/4 -> 21.365573 | BH47: =+$Q$47/4 -> 21.365573 | BI47: =+$Q$47/4 -> 21.365573 | BJ47: =+$Q$47/4 -> 21.365573 | BK47: =+$R$47/4 -> 24.581774 | BL47: =+$R$47/4 -> 24.581774 | BM47: =+$R$47/4 -> 24.581774 | BN47: =+$R$47/4 -> 24.581774 | BO47: =+$S$47/4 -> 22.663766 | BP47: =+$S$47/4 -> 22.663766 | BQ47: =+$S$47/4 -> 22.663766 | BR47: =+$S$47/4 -> 22.663766 | BS47: =+$T$47/4 -> 19.024462 | BT47: =+$T$47/4 -> 19.024462 | BU47: =+$T$47/4 -> 19.024462 | BV47: =+$T$47/4 -> 19.024462 | BW47: =+$U$47/4 -> 16.258591 | BX47: =+$U$47/4 -> 16.258591 | BY47: =+$U$47/4 -> 16.258591 | BZ47: =+$U$47/4 -> 16.258591
B48: EBITDA | C48: =+C45+C46+C47 -> 35.697081 | D48: =+D45+D46+D47 -> 54.089468 | E48: =+E45+E46+E47 -> 67.999395 | F48: =+F45+F46+F47 -> 39.707897 | G48: =+G45+G46+G47 -> 21.834186 | H48: =+H45+H46+H47 -> 22.552873 | I48: =+I45+I46+I47 -> 23.686312 | J48: =+J45+J46+J47 -> 24.031204 | ... U48: =+U45+U46+U47 -> 25508.583 | W48: =+W45+W46+W47 -> 7.9618795 | X48: =+X45+X46+X47 -> 0.5327467 | Y48: =+Y45+Y46+Y47 -> 2.075654 | Z48: =+Z45+Z46+Z47 -> 11.982593 | AA48: =+AA45+AA46+AA47 -> 1.4705508 | AB48: =+AB45+AB46+AB47 -> 6.0970747 | AC48: =+AC45+AC46+AC47 -> 5.3464822 | AD48: =+AD45+AD46+AD47 -> 10.772204 | ... BZ48: =+BZ45+BZ46+BZ47 -> 6808.8407
...

Sheet Assumption
A1: =TODAY() -> 45923
A2: Innolight (300308.SZ)
A3: (Rmb m) | B3: 1Q22 | C3: 2Q22 | D3: 3Q22 | E3: 4Q22 | F3: 1Q23 | G3: 2Q23 | H3: 3Q23 | I3: 4Q23 | J3: 1Q24 | K3: 2Q24 | L3: 3Q24 | M3: 4Q24 | N3: 1Q25 | O3: 2Q25 | P3: 3Q25E | Q3: 4Q25E | R3: 1Q26E | S3: 2Q26E | T3: 3Q26E | U3: 4Q26E | V3: 1Q27E | W3: 2Q27E | X3: 3Q27E | Y3: 4Q27E | AB3: 2014 | AC3: 2015 | AD3: 2016 | AE3: 2017 | AF3: 2018 | AG3: 2019 | AH3: 2020 | AI3: 2021 | AJ3: 2022 | AK3: 2023 | AL3: 2024 | AM3: 2025E | AN3: 2026E | AO3: 2027E | AP3: =A3 -> (Rmb m) | AQ3: Remark
A4: Net income | B4: =Model!BC40 -> 217.4126 | C4: =Model!BD40 -> 275.04257 | D4: =Model!BE40 -> 360.05326 | E4: =Model!BF40 -> 371.48243 | F4: =Model!BG40 -> 249.92027 | G4: =Model!BH40 -> 363.83251 | H4: =Model!BI40 -> 682.1151 | I4: =Model!BJ40 -> 877.65987 | ... Y4: =Model!BZ40 -> 5463.2734 | AD4: =Model!J40 -> 10.054132 | AE4: =Model!K40 -> 161.50542 | AF4: =Model!L40 -> 623.11598 | AG4: =Model!M40 -> 513.4872 | AH4: =Model!N40 -> 865.48355 | AI4: =Model!O40 -> 876.97713 | AJ4: =Model!P40 -> 1223.9909 | AK4: =Model!Q40 -> 2173.5277 | ... AO4: =Model!U40 -> 20489.235 | AP4: Net income
A5: EPS | B5: =Model!BC50 -> 0.2719 | C5: =Model!BD50 -> 0.3439 | D5: =Model!BE50 -> 0.4495 | E5: =Model!BF50 -> 0.4638 | F5: =Model!BG50 -> 0.312 | G5: =Model!BH50 -> 0.4532 | H5: =Model!BI50 -> 0.60690124 | I5: =Model!BJ50 -> 0.78088414 | ... Y5: =Model!BZ50 -> 4.8728475 | AD5: =Model!J50 -> 0.0465 | AE5: =Model!K50 -> 0.3509 | AF5: =Model!L50 -> 1.3127 | AG5: =Model!M50 -> 0.8002 | AH5: =Model!N50 -> 1.2135 | AI5: =Model!O50 -> 1.1815 | AJ5: =Model!P50 -> 1.5291 | AK5: =Model!Q50 -> 2.1529854 | ... AO5: =Model!U50 -> 18.274926 | AP5: EPS
A6: YoY | B6: =Model!BC75 -> 0.45712755 | C6: =Model!BD75 -> 0.18016472 | D6: =Model!BE75 -> 0.46178862 | E6: =Model!BF75 -> 0.17121212 | F6: =Model!BG75 -> 0.14748069 | G6: =Model!BH75 -> 0.31782495 | H6: =Model!BI75 -> 0.35016962 | I6: =Model!BJ75 -> 0.68366568 | ... Y6: =Model!BZ75 -> 0.18709814 | AD6: =Model!J75 -> 0.80933852 | AE6: =Model!K75 -> 6.5462366 | AF6: =Model!L75 -> 2.7409518 | AG6: =Model!M75 -> -0.3904167 | AH6: =Model!N75 -> 0.51649588 | AI6: =Model!O75 -> -0.026370004 | AJ6: =Model!P75 -> 0.29420229 | AK6: =Model!Q75 -> 0.40800823 | ... AO6: =Model!U75 -> 0.23948085 | AP6: YoY
A7: GM | B7: =B197 -> 0.27280443 | C7: =C197 -> 0.27441984 | D7: =D197 -> 0.2977164 | E7: =E197 -> 0.32881312 | F7: =F197 -> 0.28774532 | G7: =G197 -> 0.30441705 | H7: =H197 -> 0.33511423 | I7: =I197 -> 0.35398327 | ... Y7: =Y197 -> 0.46602934 | AD7: =AD197 -> 0 | AE7: =AE197 -> 0 | AF7: =AF197 -> 0.26712491 | AG7: =AG197 -> 0.26040669 | AH7: =AH197 -> 0.26485172 | AI7: =AI197 -> 0.27777104 | AJ7: =AJ197 -> 0.29609915 | AK7: =AK197 -> 0.32728101 | ... AO7: =AO197 -> 0.45545176 | AP7: GM
A8: OPM | B8: =Model!BC87 -> 0.11168883 | C8: =Model!BD87 -> 0.1198616 | D8: =Model!BE87 -> 0.15149166 | E8: =Model!BF87 -> 0.18350615 | F8: =Model!BG87 -> 0.14641988 | G8: =Model!BH87 -> 0.17781796 | H8: =Model!BI87 -> 0.23796138 | I8: =Model!BJ87 -> 0.22052598 | ... Y8: =Model!BZ87 -> 0.38934783 | AD8: =Model!J87 -> -0.053503501 | AE8: =Model!K87 -> 0.14729937 | AF8: =Model!L87 -> 0.14993448 | AG8: =Model!M87 -> 0.12222927 | AH8: =Model!N87 -> 0.1116915 | AI8: =Model!O87 -> 0.11678288 | AJ8: =Model!P87 -> 0.14506133 | AK8: =Model!Q87 -> 0.20411239 | ... AO8: =Model!U87 -> 0.396734 | AP8: OPM
A9: ROE | AD9: =Model!J196 -> 0.018214182 | AE9: =Model!K196 -> 0.070810234 | AF9: =Model!L196 -> 0.14190204 | AG9: =Model!M196 -> 0.087755353 | AH9: =Model!N196 -> 0.11683539 | AI9: =Model!O196 -> 0.090511863 | AJ9: =Model!P196 -> 0.10446208 | AK9: =Model!Q196 -> 0.16587867 | ... AO9: =Model!U196 -> 0.39299606 | AP9: ROE
A10: Capex / Revenue | AD10: =-Model!J216/Model!J7 -> 0.26914705 | AE10: =-Model!K216/Model!K7 -> 0.17851649 | AF10: =-Model!L216/Model!L7 -> 0.11786228 | AG10: =-Model!M216/Model!M7 -> 0.15959604 | AH10: =-Model!N216/Model!N7 -> 0.13562047 | AI10: =-Model!O216/Model!O7 -> 0.10910128 | AJ10: =-Model!P216/Model!P7 -> 0.082125227 | AK10: =-Model!Q216/Model!Q7 -> 0.15902769 | ... AO10: =-Model!U216/Model!U7 -> 0.040813956 | AP10: Capex / Revenue
A12: Revenue (Rmb million) | B12: =+Model!BC7 -> 2088.6226 | C12: =+Model!BD7 -> 2142.4212 | D12: =+Model!BE7 -> 2633.9444 | E12: =+Model!BF7 -> 2776.8065 | F12: =+Model!BG7 -> 1837.1632 | G12: =+Model!BH7 -> 2166.818 | H12: =+Model!BI7 -> 3026.3091 | I12: =+Model!BJ7 -> 3687.6941 | ... O12: =+Model!BP7 -> 8114.8984 | P12: =SUM(P13:P20) -> 9544.9328 | Q12: =SUM(Q13:Q20) -> 10707.949 | R12: =SUM(R13:R20) -> 10818.019 | S12: =SUM(S13:S20) -> 12058.533 | T12: =SUM(T13:T20) -> 13278.777 | U12: =SUM(U13:U20) -> 14427.284 | V12: =SUM(V13:V20) -> 13381.138 | W12: =SUM(W13:W20) -> 15125.613 | ... Y12: =SUM(Y13:Y20) -> 16752.354 | AB12: =Model!H7 -> 118.74621 | AC12: =Model!I7 -> 121.40994 | AD12: =Model!J7 -> 131.62038 | AE12: =Model!K7 -> 2357.0835 | AF12: =Model!L7 -> 5156.3142 | AG12: =Model!M7 -> 4757.677 | AH12: =Model!N7 -> 7049.5901 | AI12: =Model!O7 -> 7695.4048 | AJ12: =Model!P7 -> 9641.7948 | AK12: =SUM(AK13:AK20) -> 10717.984 | AL12: =SUM(AL13:AL20) -> 23862.16 | AM12: =SUM(AM13:AM20) -> 35041.957 | AN12: =SUM(AN13:AN20) -> 50582.612 | AO12: =SUM(AO13:AO20) -> 61409.384 | AP12: Revenue (Rmb million)
A13: 10G/40G | B13: =+B45 -> 162.4 | C13: =+C45 -> 182.7 | D13: =+D45 -> 182.7 | E13: =+E45 -> 140.07 | F13: =+F45 -> 156.31 | G13: =+G45 -> 178.64 | H13: =+H45 -> 156.31 | I13: =+I45 -> 156.19835 | ... Y13: =+Y45 -> 98.252 | AF13: =+AF45 -> 1248.7628 | AG13: =+AG45 -> 1029.8327 | AH13: =+AH45 -> 501.58826 | AI13: =+AI45 -> 897.05834 | AJ13: =+AJ45 -> 666.38668 | AK13: =SUM(F13:I13) -> 647.45835 | AL13: =SUM(J13:M13) -> 687.764 | AM13: =SUM(N13:Q13) -> 589.512 | AN13: =SUM(R13:U13) -> 540.386 | AO13: =SUM(V13:Y13) -> 393.008
A14: 100G | B14: =+B46 -> 1153.11 | C14: =+C46 -> 1153.11 | D14: =+D46 -> 1225.1794 | E14: =+E46 -> 792.76312 | F14: =+F46 -> 799.68178 | G14: =+G46 -> 714.00159 | H14: =+H46 -> 285.60064 | I14: =+I46 -> 285.60064 | ... Y14: =+Y46 -> 174.46763 | AF14: =+AF46 -> 3749.13 | AG14: =+AG46 -> 3600.6 | AH14: =+AH46 -> 5705.727 | AI14: =+AI46 -> 4140.922 | AJ14: =+AJ46 -> 4324.1625 | AK14: =SUM(F14:I14) -> 2084.8847 | AL14: =SUM(J14:M14) -> 797.23657 | AM14: =SUM(N14:Q14) -> 771.93964 | AN14: =SUM(R14:U14) -> 734.60054 | AO14: =SUM(V14:Y14) -> 697.87051
A15: 200G | B15: =+B47 -> 323.4 | C15: =+C47 -> 385 | D15: =+D47 -> 462 | E15: =+E47 -> 523.6 | F15: =+F47 -> 375.804 | G15: =+G47 -> 216.81 | H15: =+H47 -> 86.724 | I15: =+I47 -> 86.724 | ... Y15: =+Y47 -> 66.919491 | AF15: =+AF47 -> 0 | AG15: =+AG47 -> 0 | AH15: =+AH47 -> 30.6 | AI15: =+AI47 -> 1003 | AJ15: =+AJ47 -> 1694 | AK15: =SUM(F15:I15) -> 766.062 | AL15: =SUM(J15:M15) -> 355.6872 | AM15: =SUM(N15:Q15) -> 296.08821 | AN15: =SUM(R15:U15) -> 281.76628 | AO15: =SUM(V15:Y15) -> 267.67796
A16: 400G | B16: =+B48 -> 364 | C16: =+C48 -> 364 | D16: =+D48 -> 728 | E16: =+E48 -> 1272.18 | F16: =+F48 -> 459.9 | G16: =+G48 -> 459.9 | H16: =+H48 -> 613.2 | I16: =+I48 -> 613.2 | ... Y16: =+Y48 -> 162.84402 | AF16: =+AF48 -> 0 | AG16: =+AG48 -> 0 | AH16: =+AH48 -> 272 | AI16: =+AI48 -> 1219.92 | AJ16: =+AJ48 -> 2728.18 | AK16: =SUM(F16:I16) -> 2146.2 | AL16: =SUM(J16:M16) -> 5839.704 | AM16: =SUM(N16:Q16) -> 4009.824 | AN16: =SUM(R16:U16) -> 1085.6268 | AO16: =SUM(V16:Y16) -> 651.37608
A17: 800G | B17: =+B49+B51 -> 0 | C17: =+C49+C51 -> 0 | D17: =+D49+D51 -> 0 | E17: =+E49+E51 -> 0 | F17: =+F49+F51 -> 0 | G17: =+G49+G51 -> 551.15 | H17: =+H49+H51 -> 1846.17 | I17: =+I49+I51 -> 2525.8 | J17: =+J49+J51+J50 -> 3455.09 | K17: =+K49+K51+K50 -> 3942 | L17: =+L49+L51+L50 -> 4284 | M17: =+M49+M51+M50 -> 4032 | N17: =+N49+N51+N50 -> 4253.0312 | O17: =+O49+O51+O50 -> 6083.82 | P17: =+P49+P51+P50 -> 6542.625 | Q17: =+Q49+Q51+Q50 -> 7079.175 | ... Y17: =+Y49+Y51+Y50 -> 2819.4163 | AF17: =+AF49 -> 0 | AG17: =+AG49 -> 0 | AH17: =+AH49 -> 0 | AI17: =+AI49 -> 0 | AJ17: =+AJ49 -> 0 | AK17: =SUM(F17:I17) -> 4923.12 | AL17: =SUM(J17:M17) -> 15713.09 | AM17: =SUM(N17:Q17) -> 23958.651 | AN17: =SUM(R17:U17) -> 30152.796 | AO17: =SUM(V17:Y17) -> 18369.317
A18: 1.6T | B18: =+B52+B53 -> 0 | C18: =+C52+C53 -> 0 | D18: =+D52+D53 -> 0 | E18: =+E52+E53 -> 0 | F18: =+F52+F53 -> 0 | G18: =+G52+G53 -> 0 | H18: =+H52+H53 -> 0 | I18: =+I52+I53 -> 0 | ... Y18: =+Y52+Y53 -> 11991.007 | AF18: =+AF52 -> 0 | AG18: =+AG52 -> 0 | AH18: =+AH52 -> 0 | AI18: =+AI52 -> 0 | AJ18: =+AJ52 -> 0 | AK18: =SUM(F18:I18) -> 0 | AL18: =SUM(J18:M18) -> 299.25 | AM18: =SUM(N18:Q18) -> 5198.875 | AN18: =SUM(R18:U18) -> 17570.37 | AO18: =SUM(V18:Y18) -> 38710.668
A19: 3.2T | X19: =+X54 -> 700.8 | Y19: =+Y54 -> 1401.6 | AO19: =+AO54 -> 2102.4
A20: Components/others | B20: =+B12-SUM(B13:B18) -> 85.71265 | C20: =+C12-SUM(C13:C18) -> 57.611181 | D20: =+D12-SUM(D13:D18) -> 36.065039 | E20: =+E12-SUM(E13:E18) -> 48.193397 | F20: =+F12-SUM(F13:F18) -> 45.467431 | G20: =+G12-SUM(G13:G18) -> 46.316435 | H20: =+H12-SUM(H13:H18) -> 38.30449 | I20: =+I12-SUM(I13:I18) -> 20.171112 | J20: =+J12-J13-J14-J15-J16-J17 -> 40.45387 | K20: =+K12-K13-K14-K15-K16-K17 -> 41.580207 | L20: =+L12-L13-L14-L15-L16-L17-L18 -> 49.546802 | M20: =+M12-M13-M14-M15-M16-M17-M18 -> 37.847085 | N20: =+N12-N13-N14-N15-N16-N17-N18 -> 66.439237 | O20: =+O12-O13-O14-O15-O16-O17-O18 -> 63.233399 | P20: =+L20*(1+P30) -> 49.546802 | Q20: =+M20*(1+Q30) -> 37.847085 | R20: =+N20*(1+R30) -> 66.439237 | S20: =+O20*(1+S30) -> 63.233399 | T20: =+P20*(1+T30) -> 49.546802 | U20: =+Q20*(1+U30) -> 37.847085 | V20: =+R20*(1+V30) -> 66.439237 | W20: =+S20*(1+W30) -> 63.233399 | ... Y20: =+U20*(1+Y30) -> 37.847085 | AF20: =+AF12-SUM(AF13:AF18) -> 158.42143 | AG20: =+AG12-SUM(AG13:AG18) -> 127.24437 | AH20: =+AH12-SUM(AH13:AH18) -> 539.67486 | AI20: =+AI12-SUM(AI13:AI18) -> 434.50441 | AJ20: =+AJ12-SUM(AJ13:AJ18) -> 229.06559 | AK20: =SUM(F20:I20) -> 150.25947 | AL20: =SUM(J20:M20) -> 169.42796 | AM20: =SUM(N20:Q20) -> 217.06652 | AN20: =SUM(R20:U20) -> 217.06652 | AO20: =SUM(V20:Y20) -> 217.06652
A22: Revenue YoY | F22: =+F12/B12-1 -> -0.12039486 | G22: =+G12/C12-1 -> 0.011387512 | H22: =+H12/D12-1 -> 0.14896469 | I22: =+I12/E12-1 -> 0.32803423 | J22: =+J12/F12-1 -> 1.6358828 | K22: =+K12/G12-1 -> 1.7487529 | L22: =+L12/H12-1 -> 1.1524594 | M22: =+M12/I12-1 -> 0.77605781 | ... Y22: =+Y12/U12-1 -> 0.16115786 | AG22: =+AG12/AF12-1 -> -0.077310497 | AH22: =+AH12/AG12-1 -> 0.48172944 | AI22: =+AI12/AH12-1 -> 0.091610245 | AJ22: =+AJ12/AI12-1 -> 0.25292886 | AK22: =+AK12/AJ12-1 -> 0.11161716 | AL22: =+AL12/AK12-1 -> 1.2263663 | AM22: =+AM12/AL12-1 -> 0.46851572 | AN22: =+AN12/AM12-1 -> 0.44348709 | AO22: =+AO12/AN12-1 -> 0.21404138
A23: 10G/40G | F23: =+F13/B13-1 -> -0.0375 | G23: =+G13/C13-1 -> -0.022222222 | H23: =+H13/D13-1 -> -0.14444444 | I23: =+I13/E13-1 -> 0.11514493 | J23: =+J13/F13-1 -> 0.1 | K23: =+K13/G13-1 -> -0.0375 | L23: =+L13/H13-1 -> 0.1 | M23: =+M13/I13-1 -> 0.10078628 | ... Y23: =+Y13/U13-1 -> -0.27272727 | AG23: =+AG13/AF13-1 -> -0.17531764 | AH23: =+AH13/AG13-1 -> -0.51294197 | AI23: =+AI13/AH13-1 -> 0.78843568 | AJ23: =+AJ13/AI13-1 -> -0.25714232 | AK23: =+AK13/AJ13-1 -> -0.02840442 | AL23: =+AL13/AK13-1 -> 0.062252112 | AM23: =+AM13/AL13-1 -> -0.14285714 | AN23: =+AN13/AM13-1 -> -0.083333333 | AO23: =+AO13/AN13-1 -> -0.27272727
A24: 100G | F24: =+F14/B14-1 -> -0.3065 | G24: =+G14/C14-1 -> -0.38080357 | H24: =+H14/D14-1 -> -0.76689076 | I24: =+I14/E14-1 -> -0.63974026 | J24: =+J14/F14-1 -> -0.74553571 | K24: =+K14/G14-1 -> -0.715 | L24: =+L14/H14-1 -> -0.31678082 | M24: =+M14/I14-1 -> -0.31678082 | ... Y24: =+Y14/U14-1 -> -0.05 | AG24: =+AG14/AF14-1 -> -0.039617191 | AH24: =+AH14/AG14-1 -> 0.58466006 | AI24: =+AI14/AH14-1 -> -0.27425163 | AJ24: =+AJ14/AI14-1 -> 0.044251123 | AK24: =+AK14/AJ14-1 -> -0.51785238 | AL24: =+AL14/AK14-1 -> -0.61761118 | AM24: =+AM14/AL14-1 -> -0.031730769 | AN24: =+AN14/AM14-1 -> -0.048370497 | AO24: =+AO14/AN14-1 -> -0.05
A25: 200G | F25: =+F15/B15-1 -> 0.16204082 | G25: =+G15/C15-1 -> -0.43685714 | H25: =+H15/D15-1 -> -0.81228571 | I25: =+I15/E15-1 -> -0.83436975 | J25: =+J15/F15-1 -> -0.79230769 | K25: =+K15/G15-1 -> -0.64 | L25: =+L15/H15-1 -> 0.15068493 | M25: =+M15/I15-1 -> 0.15068493 | ... Y25: =+Y15/U15-1 -> -0.05 | AG25: 0 | AH25: 0 | AI25: =+AI15/AH15-1 -> 31.777778 | AJ25: =+AJ15/AI15-1 -> 0.6889332 | AK25: =+AK15/AJ15-1 -> -0.54777922 | AL25: =+AL15/AK15-1 -> -0.53569398 | AM25: =+AM15/AL15-1 -> -0.16756012 | AN25: =+AN15/AM15-1 -> -0.048370497 | AO25: =+AO15/AN15-1 -> -0.05
