Workbook

Sheet Transceiver pipeline
A1: 光模块需求量 | H1: From sheet "Card to Transceiver" | O1: Check Source: LightCounting | V1: Check Source: Omdia, Lightcounting
C2: 26E | D2: 27E | E2: 28E | H2: # transceivers/GPU | I2: 400G | J2: 800G | K2: 1.6T | L2: 3.2T | W2: 2028E
B3: Nvidia (k units) | H3: H20（2024） | I3: ='Card to Transceiver'!C3 -> 0 | J3: ='Card to Transceiver'!D3 -> 5 | K3: ='Card to Transceiver'!E3 -> 0 | L3: ='Card to Transceiver'!F3 -> 0 | V3: Data center switch market cap ($mn) | W3: 37332
A4: 1 | B4: 800G | C4: =SUMPRODUCT($J$3:$J$8,J$17:J$22) -> 7147.8 | D4: =SUMPRODUCT($J$3:$J$8,K$17:K$22) -> 8160 | E4: =SUMPRODUCT($J$3:$J$8,L$17:L$22) -> 3520 | H4: H100/H200 （2022-2024） | I4: ='Card to Transceiver'!C4 -> 0 | J4: ='Card to Transceiver'!D4 -> 3 | K4: ='Card to Transceiver'!E4 -> 0 | L4: ='Card to Transceiver'!F4 -> 0 | V4: >= 800G share | W4: =1-(0.3%+2.4%+3.3%+0.8%+0.3%+11.8%+0.5%+11.9%) -> 0.687
A5: 2 | B5: 1.6T | C5: =SUMPRODUCT($K$3:$K$8,J$17:J$22) -> 4674 | D5: =SUMPRODUCT($K$3:$K$8,K$17:K$22) -> 17170 | E5: =SUMPRODUCT($K$3:$K$8,L$17:L$22) -> 13112 | H5: B200/GB200 （2025） | I5: ='Card to Transceiver'!C5 -> 1 | J5: ='Card to Transceiver'!D5 -> 3 | K5: ='Card to Transceiver'!E5 -> 0 | L5: ='Card to Transceiver'!F5 -> 0 | V5: High speed switch market cap($bn) | W5: =W3*W4/1000 -> 25.647084
A6: 4 | B6: 3.2T | C6: =SUMPRODUCT($L$3:$L$8,J$17:J$22) -> 0 | D6: =SUMPRODUCT($L$3:$L$8,K$17:K$22) -> 0 | E6: =SUMPRODUCT($L$3:$L$8,L$17:L$22) -> 9108 | H6: B300/GB300 （2025） | I6: ='Card to Transceiver'!C6 -> 0 | J6: ='Card to Transceiver'!D6 -> 1 | K6: ='Card to Transceiver'!E6 -> 2.5 | L6: ='Card to Transceiver'!F6 -> 0 | V6: Hight speed transceiver market cap ($bn) | W6: =0.5+6+9.5 -> 16
B7: ASIC (k units) | H7: Rubin （2026） | I7: ='Card to Transceiver'!C7 -> 0 | J7: ='Card to Transceiver'!D7 -> 2 | K7: ='Card to Transceiver'!E7 -> 4 | L7: ='Card to Transceiver'!F7 -> 0 | V7: Switch + transceiver market cap ($bn) | W7: =SUM(W5:W6) -> 41.647084
B8: 800G | C8: =J$26 * J10 -> 8756 | D8: =K$26 * K10 -> 5473 | E8: =L$26 * L10 -> 0 | H8: Rubin Ultra （2027） | I8: ='Card to Transceiver'!C8 -> 0 | J8: ='Card to Transceiver'!D8 -> 0 | K8: ='Card to Transceiver'!E8 -> 2 | L8: ='Card to Transceiver'!F8 -> 3 | V8: CPO penetration rate | W8: 0.1
B9: 1.6T | C9: =J$26 * J11 -> 6567 | D9: =K$26 * K11 -> 10946 | E9: =L$26 * L11 -> 18879 | H9: # transceivers/ASIC | I9: 25E | J9: 26E | K9: 27E | L9: 28E | V9: CPO market cap ($bn) | W9: =W7*W8 -> 4.1647084
B10: 3.2T | C10: =J$26 * J12 -> 0 | D10: =K$26 * K12 -> 5473 | E10: =L$26 * L12 -> 12586 | H10: 800G | I10: ='Card to Transceiver'!C17 -> 3 | J10: ='Card to Transceiver'!D17 -> 2 | K10: ='Card to Transceiver'!E17 -> 1 | L10: ='Card to Transceiver'!F17 -> 0
H11: 1.6T | I11: ='Card to Transceiver'!C18 -> 0 | J11: ='Card to Transceiver'!D18 -> 1.5 | K11: ='Card to Transceiver'!E18 -> 2 | L11: ='Card to Transceiver'!F18 -> 3
B12: Summary (mn units) | C12: 26E | D12: 27E | E12: 28E | H12: 3.2T | I12: ='Card to Transceiver'!C19 -> 0 | J12: ='Card to Transceiver'!D19 -> 0 | K12: ='Card to Transceiver'!E19 -> 1 | L12: ='Card to Transceiver'!F19 -> 2
B13: 800G | C13: =SUM(C4,C8) / 1000 -> 15.9038 | D13: =SUM(D4,D8) / 1000 -> 13.633 | E13: =SUM(E4,E8) / 1000 -> 3.52
B14: 1.6T | C14: =SUM(C5,C9) / 1000 -> 11.241 | D14: =SUM(D5,D9) / 1000 -> 28.116 | E14: =SUM(E5,E9) / 1000 -> 31.991
B15: 3.2T | C15: =SUM(C6,C10) / 1000 -> 0 | D15: =SUM(D6,D10) / 1000 -> 5.473 | E15: =SUM(E6,E10) / 1000 -> 21.694 | H15: From sheet "GPU pipeline"
H16: Nvidia AI GPU Shipments Estimates​(k units) | I16: 25E | J16: 26E | K16: 27E | L16: 28E
A17: CPO在各速率光模块的渗透率 | H17: H20（2024） | I17: / | J17: ='GPU pipeline'!C3 -> 0 | K17: ='GPU pipeline'!D3 -> 0 | L17: ='GPU pipeline'!E3 -> 0
C18: 26E | D18: 27E | E18: 28E | H18: H100/H200 （2022-2024） | I18: / | J18: ='GPU pipeline'!C4 -> 150 | K18: ='GPU pipeline'!D4 -> 0 | L18: ='GPU pipeline'!E4 -> 0
B19: 800G | C19: 0.01 | D19: 0.05 | E19: 0.01 | H19: B200/GB200 （2025） | I19: / | J19: ='GPU pipeline'!C5 -> 1609.4 | K19: ='GPU pipeline'!D5 -> 0 | L19: ='GPU pipeline'!E5 -> 0
B20: 1.6T | C20: 0.02 | D20: 0.04 | E20: 0.08 | H20: B300/GB300 （2025） | I20: / | J20: ='GPU pipeline'!C6 -> 1869.6 | K20: ='GPU pipeline'!D6 -> 1700 | L20: ='GPU pipeline'!E6 -> 0
B21: 3.2T | C21: 0 | D21: 0.03 | E21: 0.15 | H21: Rubin （2026） | I21: / | J21: ='GPU pipeline'!C7 -> 0 | K21: ='GPU pipeline'!D7 -> 3230 | L21: ='GPU pipeline'!E7 -> 1760
H22: Rubin Ultra （2027） | I22: / | J22: ='GPU pipeline'!C8 -> 0 | K22: ='GPU pipeline'!D8 -> 0 | L22: ='GPU pipeline'!E8 -> 3036
A23: 光模块单价（美元） | C23: 26E | D23: 27E | E23: 28E | H23: Sum | J23: ='GPU pipeline'!C9 -> 3629 | K23: ='GPU pipeline'!D9 -> 4930 | L23: ='GPU pipeline'!E9 -> 4796
B24: 800G | C24: 500 | D24: =C24*0.7 -> 350 | E24: =D24*0.8 -> 280 | H24: From sheet "ASIC pipeline"
B25: 1.6T | C25: 1000 | D25: =C25*0.7 -> 700 | E25: =D25*0.8 -> 560 | H25: IDC ASIC Chip Shipment Estimates(k units) | I25: 25E | J25: 26E | K25: 27E | L25: 28E
B26: 3.2T | C26: 2000 | D26: =C26*0.7 -> 1400 | E26: =D26*0.8 -> 1120 | H26: ASIC chip | I26: / | J26: ='ASIC pipeline'!C8 -> 4378 | K26: ='ASIC pipeline'!D8 -> 5473 | L26: ='ASIC pipeline'!E8 -> 6293
A28: CPO整机平摊到每端口的价值 | C28: 26E | D28: 27E | E28: 28E
B29: 800G | C29: =ROUND(100000/144 * 0.85/100, 0) * 100 -> 600 | D29: =ROUND(C29*0.7, 0) -> 420 | E29: =ROUND(D29*0.8/100, 1)*100 -> 340
B30: 1.6T | C30: =C29*2 -> 1200 | D30: =ROUND(C30*0.7, 0) -> 840 | E30: =ROUND(D30*0.8/100, 1)*100 -> 670
B31: 3.2T | C31: =C30*2 -> 2400 | D31: =ROUND(C31*0.7, 0) -> 1680 | E31: =ROUND(D31*0.8/100, 1)*100 -> 1340
A33: CPO市场规模
C34: 26E | D34: 27E | E34: 28E
B35: 总CPO端口数 (mn units) | C35: =SUMPRODUCT(C13:C15,C19:C21) -> 0.383858 | D35: =SUMPRODUCT(D13:D15,D19:D21) -> 1.97048 | E35: =SUMPRODUCT(E13:E15,E19:E21) -> 5.84858
B36: CPO渗透率 | C36: =C35/SUM(C13:C15) -> 0.014141125 | D36: =D35/SUM(D13:D15) -> 0.041728008 | E36: =E35/SUM(E13:E15) -> 0.10223897
B37: 各速率规模 ($bn)
B38: 800G | C38: =C13*C19*C29 / 1000 -> 0.0954228 | D38: =D13*D19*D29 / 1000 -> 0.286293 | E38: =E13*E19*E29 / 1000 -> 0.011968
B39: 1.6T | C39: =C14*C20*C30 / 1000 -> 0.269784 | D39: =D14*D20*D30 / 1000 -> 0.9446976 | E39: =E14*E20*E30 / 1000 -> 1.7147176
B40: 3.2T | C40: =C15*C21*C31 / 1000 -> 0 | D40: =D15*D21*D31 / 1000 -> 0.2758392 | E40: =E15*E21*E31 / 1000 -> 4.360494
B41: 总规模 ($bn) | C41: =SUM(C38:C40) -> 0.3652068 | D41: =SUM(D38:D40) -> 1.5068298 | E41: =SUM(E38:E40) -> 6.0871796
B42: yoy | D42: =D41/C41-1 -> 3.1259632 | E42: =E41/D41-1 -> 3.0397261
...

Sheet Card to Transceiver
A1: Attach Ratio（配比） of Transceiver to GPU/ASIC | C1: 0.5 | D1: 1 | E1: 2 | F1: 4 | N1: 配比的测算过程示例 | AC1: Source: LightCounting，光模块各速率渗透率
B2: # transceivers/GPU | C2: 400G | D2: 800G | E2: 1.6T | F2: 3.2T | G2: 等效800G | H2: Notes | N2: 1. 光模块配比取决于：网卡型号、交换机型号、组网架构（单元数量） | AC2: 年份 | AD2: 800G | AE2: 1.6T | AF2: 3.2T
B3: H20（2024） | D3: 5 | E3: 0 | F3: 0 | G3: =SUMPRODUCT(C3:F3, $C$1:$F$1) -> 5 | H3: 网平专家反馈普遍为1:5，因5k卡以上大集群占比高导致配比高 | N3: 2. 网卡型号在DGX中常与GPU卡绑定，对光模块测算影响可先忽略 | AC3: 2022 | AD3: 0 | AE3: 0 | AF3: 0
B4: H100/H200 （2022-2024） | C4: 0 | D4: 3 | E4: 0 | F4: 0 | G4: =SUMPRODUCT(C4:F4, $C$1:$F$1) -> 3 | N4: 3. 计算单元越多，层级越高，配比越高。英伟达给出的示例方案中普遍采用两层架构（2-layer spine-leaf fat-tree） | AC4: 2023 | AD4: 1 | AE4: 0 | AF4: 0
B5: B200/GB200 （2025） | C5: 1 | D5: 3 | E5: 0 | F5: 0 | G5: =SUMPRODUCT(C5:F5, $C$1:$F$1) -> 3.5 | N5: 4. 交换机端口数会影响所需交换机数，进而影响组网架构，但总的换算端口数在fat-tree下几乎不受影响，因为fat-tree要求无阻塞网络，上行和下行带宽需相等 | AC5: 2024 | AD5: 1 | AE5: 0 | AF5: 0
B6: B300/GB300 （2025） | C6: 0 | D6: 1 | E6: 2.5 | F6: 0 | G6: =SUMPRODUCT(C6:F6, $C$1:$F$1) -> 6 | O6: # tansceivers in DGX GB200 (8机架，两层组网架构) | T6: Source: Goldman (2025.07) | AC6: 2025 | AD6: 0.87764706 | AE6: 0.12235294 | AF6: 0
B7: Rubin （2026） | C7: 0 | D7: 2 | E7: 4 | F7: 0 | G7: =SUMPRODUCT(C7:F7, $C$1:$F$1) -> 10 | H7: 参考调研纪要公众号披露，Rubin对光模块的需求量是GB300的2x，且部分转向1.6T | O7: 互连层级 | P7: 硬件层级 | R7: Note | T7: GB200 NVL72 | AC7: 2026 | AD7: 0.72596844 | AE7: 0.27403156 | AF7: 0
B8: Rubin Ultra （2027） | E8: 2 | F8: 3 | G8: =SUMPRODUCT(C8:F8, $C$1:$F$1) -> 16 | H8: 部分转向3.2T | O8: 计算网络 | AC8: 2027 | AD8: 0.6199095 | AE8: 0.33823529 | AF8: 0.041855204
O9: Spine交换机侧 | P9: 下行带宽（GB/s） | Q9: =Q12 -> 230400 | R9: Spine的总下行带宽=Leaf的总上行带宽 | AC9: 2028 | AD9: 0.49048443 | AE9: 0.42906574 | AF9: 0.080449827
B10: # transceivers/ASIC | C10: 400G | D10: 800G | E10: 1.6T | F10: 3.2T | G10: 等效800G | H10: Notes | P10: Spine层所需800G数量 | Q10: =Q9/800 -> 288 | AC10: 2029 | AD10: 0.39144957 | AE10: 0.46893788 | AF10: 0.13961256
B11: 2025 | C11: / | D11: 3 | E11: 0 | F11: 0 | G11: 3 | H11: 高：Meta，1:8 中：GCP，1:3 低：AWS, 1:1.5 （当前铜互连为主） | O11: Leaf交换机侧 | P11: 下行带宽（GB/s） | Q11: =Q20*400 -> 230400
B12: 2026 | C12: / | D12: 2 | E12: 1.5 | F12: 0 | G12: =SUMPRODUCT($C$1:$F$1,C12:F12) -> 5 | H12: 比例 1:1:0 | P12: 上行带宽（GB/s） | Q12: =Q11 -> 230400 | AC12: 等效800G数量分配
B13: 2027 | C13: / | D13: 1 | E13: 2 | F13: 1 | G13: =SUMPRODUCT($C$1:$F$1,C13:F13) -> 9 | H13: 比例 1:2:1 | P13: Leaf层所需800G数量 | Q13: =SUM(Q11:Q12)/800 -> 576 | AD13: 800G | AE13: 1.6T | AF13: 3.2T
B14: 2028 | C14: / | D14: 0 | E14: 3 | F14: 2 | G14: =SUMPRODUCT($C$1:$F$1,C14:F14) -> 14 | H14: 比例 1:3:2 | O14: 机架侧 | P14: 单机架的GB200数量 | Q14: 36 | R14: 18个计算托盘，每托盘2x GB200 | AC14: 2022 | AD14: 0 | AE14: 0 | AF14: 0
P15: 单GB200含B200数量 | Q15: 2 | AC15: 2023 | AD15: 1 | AE15: 0 | AF15: 0
B16: # transceivers/ASIC | C16: 2025 | D16: 2026 | E16: 2027 | F16: 2028 | P16: 单机架含B200数量 | Q16: =Q14*Q15 -> 72 | AC16: 2024 | AD16: 1 | AE16: 0 | AF16: 0
B17: 800G | C17: =D11 -> 3 | D17: =D12 -> 2 | E17: =D13 -> 1 | F17: =D14 -> 0 | P17: 单B200所需400G光模块数量 | Q17: 1 | R17: 每个B200对应1个CX-7网卡，每个CX-7网卡带有1个400G端口 | AC17: 2025 | AD17: 0.78197065 | AE17: 0.21802935 | AF17: 0
B18: 1.6T | C18: =E11 -> 0 | D18: =E12 -> 1.5 | E18: =E13 -> 2 | F18: =E14 -> 3 | P18: 单机架所需400G光模块数量 | Q18: =Q16*Q17 -> 72 | AC18: 2026 | AD18: 0.56981982 | AE18: 0.43018018 | AF18: 0 | AG18: 6:4:0
B19: 3.2T | C19: =F11 -> 0 | D19: =F12 -> 0 | E19: =F13 -> 1 | F19: =F14 -> 2 | P19: 机架数 | Q19: 8 | W19: s | AC19: 2027 | AD19: 0.42349304 | AE19: 0.46213292 | AF19: 0.11437403 | AG19: 2:2:1
P20: 8机架所需400G数量 | Q20: =Q18*Q19 -> 576 | R20: 图示中，每rack最终连接了4台leaf交换机，为什么？ 1. leaf交换机总共只有18个800G端口，一部分分配给上行（一般情况下是上行9个，下行9个）。 2. 每rack共72 * 400G = 36 * 800G，需要连接4 * leaf交换机，这是由无阻塞网络要求的。 3. leaf-spine的全连接则是由"GPU-leaf-spine-GPU"的任意实现要求。 | AC20: 2028 | AD20: 0.29363024 | AE20: 0.51372346 | AF20: 0.1926463 | AG20: 3:5:2
P21: 8机架所需800G数量 | Q21: =SUM(Q10+Q13) -> 864 | AC21: 2029 | AD21: 0.20736023 | AE21: 0.49681529 | AF21: 0.29582449 | AG21: 2:5:3
B22: Source: Goldman (2025.07) | O22: 存储网络 | P22: 8机架所需800G数量 | Q22: 112 | R22: 存储网络也需要两层交换机，总带宽为计算网络的1/7-1/6
E23: Source: 调研纪要公众号（Founder Park转载） | F23: https://mp.weixin.qq.com/s/fLrJ6WHs1FMN587dXfuk9Q | O23: 汇总 | P23: 8机架所需400G数量 | Q23: =Q20 -> 576
P24: 8机架所需800G数量 | Q24: =SUM(Q21,Q22) -> 976
T33: Meta DSF大规模集群
B46: Source: More Than Semi 公众号
B47: 公司 | C47: https://mp.weixin.qq.com/s/8TJyPkgyP0Z2LaZCBT5VTw
B48: 英伟达 | C48: 配比关系 | D48: 关键说明
C49: 1:3-1:4.5 | D49: 1、针对三层架构应用侧 / 推理侧
D50: 2、对应 800G 光模块，与 NVLink 相关
B51: 谷歌 | D51: 3、NVL72 机柜与普通八卡服务器三层架构配比区别不大
B52: AWS | C52: 约 1:14 | D52: 2026 年需求较可观
C53: 当前 1:4；自研 ASIC 后预计 1:8 | D53: 1、自研 ASIC 后架构或从三层变四层，配比略增
B54: Meta | D54: 2、非全 800G，含 400G、200G、100G 光模块
C55: 实际 1:12-1:14（网传 1:16 为多规格总和） | D55: 1、1:12 配比中，约 8 个 800G、2 个 400G、2 个 100G
D56: 2、自研 ASIC 后架构层数增加，光模块用量上升
B58: Source: 江南捞鱼人 公众号
C59: https://mp.weixin.qq.com/s/IBvWDer71WeZ7M0Krcmm9A | U59: N | V59: 576 | W59: 9216
U60: g | V60: 72 | W60: 72
U61: p | V61: 72 | W61: 72
...

Sheet GPU pipeline
A1: Nvidia AI GPU Shipments Estimates​ | J1: HSBC 汇总 | P1: HSBC原始表
B2: (k units) | C2: 26E | D2: 27E | E2: 28E | K2: GPU Units | L2: FY2026e | M2: FY2027e | N2: FY2028e | R2: FY2026e | S2: FY2027e | T2: FY2028e | V2: Server Rack Units | W2: FY2026e | X2: FY2027e | Y2: FY2028e
B3: H20 | C3: 0 | D3: 0 | E3: 0 | K3: ​GPU Units – CoWoS-S Based​ | Q3: ​Total CoWoS capacity consumption​ | R3: 284214 | S3: 480317 | T3: 532889 | V3: ​GPUs available for NVL server rack​
B4: H200 | C4: 150 | D4: 0 | E4: 0 | K4: H200 | L4: 150000 | M4: – | N4: – | Q4: ​​- y-o-y chg​ | R4: 0.7 | S4: 0.69 | T4: 0.11 | V4: Blackwell GPUs available for GB200 | W4: 1274400 | X4: - | Y4: -
B5: B200 | C5: =SUM(L7,L12) / 1000 -> 1609.4 | D5: =SUM(M7,M12) / 1000 -> 0 | E5: =SUM(N7,N12) / 1000 -> 0 | K5: H20 | L5: 850000 | M5: – | N5: – | Q5: ​Mix​ | V5: Blackwell GPUs available for GB300 (Blackwell Ultra) | W5: 1569600 | X5: 1440000 | Y5: 1440000
B6: B300 | C6: =SUM(L8,L13) / 1000 -> 1869.6 | D6: =SUM(M8,M13) / 1000 -> 1700 | E6: =SUM(N8,N13) / 1000 -> 0 | K6: ​GPU Units – CoWoS-L Based (HGX/NVL)​​ | Q6: CoWoS-S | R6: 0.13 | S6: 0 | T6: 0 | V6: Rubin Ultra GPUs available for Rubin Ultra NVL 576 | W6: - | X6: 2880000 | Y6: 2736000
B7: Rubin | C7: =SUM(L9,L14) / 1000 -> 0 | D7: =SUM(M9,M14) / 1000 -> 3230 | E7: =SUM(N9,N14) / 1000 -> 1760 | K7: B200 | L7: 335000 | M7: – | N7: – | Q7: CoWoS-L | R7: 0.87 | S7: 1 | T7: 1 | V7: ​GPUs per rack​
B8: Rubin Ultra | C8: =SUM(L10,L15) / 1000 -> 0 | D8: =SUM(M10,M15) / 1000 -> 0 | E8: =SUM(N10,N15) / 1000 -> 3036 | K8: B300 (Blackwell Ultra) | L8: 300000 | M8: 260000 | N8: – | Q8: CoWoS-S wafers | R8: 35714 | S8: - | T8: - | V8: GB200/GB300 NVL 72 | W8: 72 | X8: 72 | Y8: -
B9: SUM | C9: =SUM(C3:C8) -> 3629 | D9: =SUM(D3:D8) -> 4930 | E9: =SUM(E3:E8) -> 4796 | K9: Rubin | L9: – | M9: 350000 | N9: 320000 | Q9: CoWoS-L wafers | R9: 248500 | S9: 480317 | T9: 532889 | V9: Vera Rubin NVL 144 | W9: 144 | X9: 144 | Y9: 144
K10: Rubin Ultra | L10: – | M10: – | N10: 300000 | Q10: ​Net die​ | V10: Rubin Ultra NVL 576 | W10: 576 | X10: 576 | Y10: 576
K11: ​GPU Units – NVL Racks​ | Q11: CoWoS-S | R11: 28 | S11: 28 | T11: 28 | V11: ​NVL racks (units)​​
K12: B200 (GB200) | L12: 1274400 | M12: – | N12: – | Q12: CoWoS-L Blackwell Die | R12: 14 | S12: 14 | T12: 14 | V12: GB200 NVL 72 | W12: 17700 | X12: - | Y12: -
K13: B300 (GB300) | L13: 1569600 | M13: 1440000 | N13: – | Q13: CoWoS-L Rubin Die | R13: 9 | S13: 9 | T13: 9 | V13: GB300 NVL 72 (Blackwell Ultra) | W13: 21800 | X13: 20000 | Y13: -
K14: Rubin (Vera Rubin NVL) | L14: – | M14: 2880000 | N14: 1440000 | Q14: ​Units - GPUs based on CoWoS-S​ | V14: ​Total Blackwell racks​ | W14: ​39,500​ | X14: ​20,000​ | Y14: ​​-​
K15: Rubin Ultra (Rubin Ultra NVL) | L15: – | M15: – | N15: 2736000 | Q15: H200 | R15: 150000 | S15: - | T15: - | V15: Vera Rubin NVL 144 | W15: - | X15: 20000 | Y15: 20000
Q16: H20 | R16: 850000 | S16: - | T16: - | V16: Rubin Ultra NVL 576 | W16: - | X16: 20000 | Y16: 19000
K17: Server Rack Units | Q17: ​Total AI GPUs based on CoWoS-S​ | R17: ​1,000,000​ | S17: - | T17: - | V17: ​Total Rubin racks​ | W17: ​​-​ | X17: ​40,000​ | Y17: ​39,000​
K18: GB200 NVL 72 | L18: 17700 | M18: - | N18: - | Q18: ​Units - GPUs for NVL (Based on CoWoS-L)​​ | V18: ​Total racks​ | W18: ​39,500​ | X18: ​60,000​ | Y18: ​39,000​
K19: GB300 NVL 72 (Blackwell Ultra) | L19: 21800 | M19: 20000 | N19: - | Q19: HGX variants/NVL 16 | V19: ​​- y-o-y change​ | W19: - | X19: 0.52 | Y19: -0.35
K20: Vera Rubin NVL 144 | L20: - | M20: 20000 | N20: 20000 | Q20: B200 | R20: 335000 | S20: - | T20: - | V20: ​ASP (USD)​​
K21: Rubin Ultra NVL 576 | L21: - | M21: 20000 | N21: 19000 | Q21: B300 (Blackwell Ultra) | R21: 300000 | S21: 260000 | T21: - | V21: GB200 NVL 72 | W21: 2623500 | X21: - | Y21: -
Q22: Rubin | R22: - | S22: 350000 | T22: 320000 | V22: GB300 NVL 72 (Blackwell Ultra) | W22: 2983500 | X22: 2983500 | Y22: -
Q23: Rubin Ultra | R23: - | S23: - | T23: 300000 | V23: Vera Rubin NVL 144 | W23: - | X23: 3159000 | Y23: 3159000
Q24: ​Total GPUs for HGX/NVL 16​ | R24: ​635,000​ | S24: ​610,000​ | T24: ​620,000​ | V24: Rubin Ultra NVL 576 | W24: - | X24: 8182800 | Y24: 8812800
Q25: For NVL racks | V25: ​Revenue (USDm)​​
J26: Source: HSBC (2025.08) | Q26: B200 for GB200 | R26: 1274400 | S26: - | T26: - | V26: GB200 NVL 72 revenue | W26: 46436 | X26: - | Y26: -
Q27: B300 for GB300 (Blackwell Ultra) | R27: 1569600 | S27: 1440000 | T27: - | V27: GB300 NVL 72 revenue | W27: 65040 | X27: 59670 | Y27: -
Q28: Rubin for Vera Rubin NVL 144 | R28: - | S28: 2880000 | T28: 1440000 | V28: ​Total Blackwell rack revenue​ | W28: ​111,476​ | X28: ​59,670​ | Y28: ​​-​
Q29: Rubin Ultra for Rubin Ultra NVL 576 | R29: - | S29: - | T29: 2736000 | V29: Vera Rubin NVL 144 revenue | W29: - | X29: 63180 | Y29: 63180
Q30: ​Total GPUs for NVL (Based on CoWoS-L)​​ | R30: ​2,844,000​ | S30: ​4,320,000​ | T30: ​4,176,000​ | V30: Rubin Ultra NVL 576 revenue | W30: - | X30: 163656 | Y30: 167443
Q31: ​Total AI GPUs based on CoWoS-L​ | R31: ​3,479,000​ | S31: ​4,930,000​ | T31: ​4,796,000​ | V31: ​Total Rubin rack revenue​ | W31: ​​-​ | X31: ​226,836​ | Y31: ​230,623​
Q32: ​​- y-o-y chg​ | R32: 10.19 | S32: 0.42 | T32: -0.03 | V32: ​Total NVL server rack revenue​ | W32: ​111,476​ | X32: ​286,506​ | Y32: ​230,623​
Q33: ​Total AI GPU units based on CoWoS​ | R33: ​4,479,000​ | S33: ​4,930,000​ | T33: ​4,796,000​ | V33: ​​- y-o-y change​ | W33: 36.16 | X33: 1.57 | Y33: -0.195
Q34: L series (not based on CoWoS) | R34: 800000 | S34: 400000 | T34: 100000
Q35: RTX 6000D | R35: 1440000 | S35: 2000000 | T35: 1000000
Q36: RTX Pro 6000 | R36: 106000 | S36: - | T36: -
Q37: ​Total AI GPU units​ | R37: ​6,825,000​ | S37: ​7,330,000​ | T37: ​5,896,000​
Q38: ​Mix by series​
Q39: Hopper | R39: 0.16 | S39: 0 | T39: 0
Q40: Blackwell | R40: 0.5 | S40: 0.23 | T40: 0
...

Sheet ASIC pipeline
A1: 数据中心ASIC chip出货量预测：情形一 | H1: Source: Goldman Sachs | R1: Source: Marvell
C2: 26E | D2: 27E | E2: 28E | F2: Note | H2: (k units) | I2: 2022 | J2: 2023 | K2: 2024 | L2: 2025E | M2: 2026E | N2: 2027E | O2: 2028E | P2: 24-28 CAGR
B3: ASIC chip volume share | C3: 0.4 | D3: 0.43 | E3: 0.45 | F3: 参考高盛测算中隐含的2026年ASIC市占率40% | H3: Total datacenter Al chip volumes | I3: 2153 | J3: 3632 | K3: 7815 | L3: 10030 | M3: 11061 | N3: 12642 | O3: 13842 | P3: 15%
B4: ASIC volume yoy | C4: 0.1 | D4: 0.25 | E4: 0.15 | F4: 参考高盛测算中27、28年yoy分别为25%和15% | H4: YoY growth | J4: 69% | K4: 115% | L4: 28% | M4: 10% | N4: 14% | O4: 9%
B5: ASIC chip (k units) | C5: ='GPU pipeline'!C9 * 1/(1/C3 - 1) -> 2419.3333 | D5: =C5*(1+D4) -> 3024.1667 | E5: =D5*(1+E4) -> 3477.7917 | H5: High end datacenter GPU volumes | I5: 800 | J5: 1931 | K5: 4950 | L5: 6050 | M5: 6683 | N5: 7169 | O5: 7549 | P5: 11%
H6: YoY growth | J6: 141% | K6: 156% | L6: 22% | M6: 10% | N6: 7% | O6: 5%
A7: 数据中心ASIC chip出货量预测：情形二（符合出货量预期） | C7: 26E | D7: 27E | E7: 28E | H7: ASIC chip volume | I7: 1353 | J7: 1701 | K7: 2865 | L7: 3980 | M7: 4378 | N7: 5473 | O7: 6293 | P7: 22%
B8: ASIC chip (k units) | C8: 4378 | D8: 5473 | E8: 6293 | H8: YoY growth | J8: 26% | K8: 68% | L8: 39% | M8: 10% | N8: 25% | O8: 15%
H9: ASIC chip volume share | I9: =I7/I3 -> 0.62842545 | J9: =J7/J3 -> 0.468337 | K9: =K7/K3 -> 0.36660269 | L9: =L7/L3 -> 0.39680957 | M9: =M7/M3 -> 0.39580508 | N9: =N7/N3 -> 0.43292201 | O9: =O7/O3 -> 0.45463083
H10: Chip per server
H11: Chip per ASIC server | I11: 5 | J11: 5 | K11: 7 | L11: 7 | M11: 8 | N11: 9 | O11: 9
H12: GPU per server
A13: 采用市场规模交叉验证 | H13: GB structure | K13: 4 | L13: 4 | M13: 4 | N13: 4 | O13: 4
C14: 2023 | D14: 2028E | E14: Note | H14: HGX structure | I14: 8 | J14: 8 | K14: 8 | L14: 8 | M14: 8 | N14: 8 | O14: 8
B15: 市场规模 ($bn) | C15: 6.6 | D15: 55.4 | H15: Total Al server volumes | I15: 401 | J15: 577 | K15: 1,066 | L15: 1,817 | M15: 1,988 | N15: 2,228 | O15: 23% | P15: 23%
B16: ASP ($) | C16: 5000 | D16: 5000 | E16: 约为NV的1/5 | H16: YoY growth | J16: 44% | K16: 85% | L16: 70% | M16: 9% | N16: 12% | O16: 8%
B17: 出货量 (mn) | C17: =C15 * 1000/C16 -> 1.32 | D17: =D15 * 1000/D16 -> 11.08 | E17: 基本align | H17: High end GPU Al server shipment | I17: 100 | J17: 241 | K17: 635 | L17: 1,231 | M17: 1,440 | N17: 1,584 | O17: 28% | P17: 28%
H18: YoY growth | J18: 141% | K18: 163% | L18: 94% | M18: 17% | N18: 10% | O18: 8%
H19: AI ASIC server shipment | I19: 301 | J19: 336 | K19: 432 | L19: 585 | M19: 547 | N19: 644 | O19: 699 | P19: 13%
H20: YoY growth | J20: 12% | K20: 28% | L20: 36% | M20: -7% | N20: 18% | O20: 9%
H21: Global server shipment(mn units) | I21: 13.8 | J21: 11.4 | K21: 12.1 | L21: 12.3 | M21: 12.3 | N21: 12.7 | O21: 13.1 | P21: 2%
H22: Total Al server% mix | I22: 2.9% | J22: 5.1% | K22: 8.8% | L22: 14.7% | M22: 16.1% | N22: 17.6% | O22: 18.4%
H23: High end GPU Al server% mix | I23: 0.7% | J23: 2.1% | K23: 5.3% | L23: 10.0% | M23: 11.7% | N23: 12.5% | O23: 13.0%
H24: ASIC chip per servers | I24: 2.2% | J24: 3.0% | K24: 3.6% | L24: 4.7% | M24: 4.4% | N24: 5.1% | O24: 5.3%
